2021-12-02T19:37:04|CRITICAL|root|Unhandled exception:Traceback (most recent call last):
  File "C:\Users\RAMAN\workspace\NearField\ScopeFoundry\hardware.py", line 220, in enable_connection
    raise err
  File "C:\Users\RAMAN\workspace\NearField\ScopeFoundry\hardware.py", line 210, in enable_connection
    self.connect()
  File "C:\Users\RAMAN\workspace\NearField\ScopeFoundryHW\aist_nt_remote_spm_rpc\remote_spm_hw.py", line 53, in connect
    remote_spm.setProperty("Ice.ACM.Client", "0")
  File "C:\Users\RAMAN\workspace\NearField\ScopeFoundryHW\aist_nt_remote_spm_rpc\RemoteSpm_ice.py", line 31, in setProperty
    return _M_RemoteSpmRPC.RemoteSpm._op_setProperty.invoke(self, ((prop, val), context))
Ice.ObjectNotExistException: exception ::Ice::ObjectNotExistException
{
    id = 
    {
        name = router
        category = Glacier2
    }
    facet = 
    operation = setProperty
}

