2021-12-02T20:05:00|CRITICAL|root|Unhandled exception:Traceback (most recent call last):
  File "C:\Users\RAMAN\workspace\NearField\ScopeFoundry\hardware.py", line 220, in enable_connection
    raise err
  File "C:\Users\RAMAN\workspace\NearField\ScopeFoundry\hardware.py", line 210, in enable_connection
    self.connect()
  File "C:\Users\RAMAN\workspace\NearField\ScopeFoundryHW\aist_nt_remote_spm_rpc\remote_spm_hw.py", line 50, in connect
    raise RuntimeError(f"{self.name} Invalid proxy")
RuntimeError: remote_spm_hw Invalid proxy

2021-12-02T20:05:27|CRITICAL|root|Unhandled exception:Traceback (most recent call last):
  File "C:\Users\RAMAN\workspace\NearField\ScopeFoundry\hardware.py", line 220, in enable_connection
    raise err
  File "C:\Users\RAMAN\workspace\NearField\ScopeFoundry\hardware.py", line 210, in enable_connection
    self.connect()
  File "C:\Users\RAMAN\workspace\NearField\ScopeFoundryHW\aist_nt_remote_spm_rpc\remote_spm_hw.py", line 53, in connect
    remote_spm.start()
  File "C:\Users\RAMAN\workspace\NearField\ScopeFoundryHW\aist_nt_remote_spm_rpc\RemoteSpm_ice.py", line 56, in start
    return _M_RemoteSpmRPC.RemoteSpm._op_start.invoke(self, ((), context))
Ice.OperationNotExistException: exception ::Ice::OperationNotExistException
{
    id = 
    {
        name = myTestAdapter
        category = 
    }
    facet = 
    operation = start
}

2021-12-02T20:08:24|CRITICAL|root|Unhandled exception:Traceback (most recent call last):
  File "C:\Users\RAMAN\workspace\NearField\ScopeFoundry\hardware.py", line 220, in enable_connection
    raise err
  File "C:\Users\RAMAN\workspace\NearField\ScopeFoundry\hardware.py", line 210, in enable_connection
    self.connect()
  File "C:\Users\RAMAN\workspace\NearField\ScopeFoundryHW\aist_nt_remote_spm_rpc\remote_spm_hw.py", line 53, in connect
    remote_spm.start()
  File "C:\Users\RAMAN\workspace\NearField\ScopeFoundryHW\aist_nt_remote_spm_rpc\RemoteSpm_ice.py", line 56, in start
    return _M_RemoteSpmRPC.RemoteSpm._op_start.invoke(self, ((), context))
Ice.OperationNotExistException: exception ::Ice::OperationNotExistException
{
    id = 
    {
        name = myTestAdapter
        category = 
    }
    facet = 
    operation = start
}

2021-12-02T20:09:00|CRITICAL|root|Unhandled exception:Traceback (most recent call last):
  File "C:\Users\RAMAN\workspace\NearField\ScopeFoundry\hardware.py", line 220, in enable_connection
    raise err
  File "C:\Users\RAMAN\workspace\NearField\ScopeFoundry\hardware.py", line 210, in enable_connection
    self.connect()
  File "C:\Users\RAMAN\workspace\NearField\ScopeFoundryHW\aist_nt_remote_spm_rpc\remote_spm_hw.py", line 53, in connect
    remote_spm.setProperty("Ice.ACM.Client", "0")
  File "C:\Users\RAMAN\workspace\NearField\ScopeFoundryHW\aist_nt_remote_spm_rpc\RemoteSpm_ice.py", line 32, in setProperty
    return _M_RemoteSpmRPC.RemoteSpm._op_setProperty.invoke(self, ((prop, val), context))
Ice.OperationNotExistException: exception ::Ice::OperationNotExistException
{
    id = 
    {
        name = myTestAdapter
        category = 
    }
    facet = 
    operation = setProperty
}

2021-12-02T20:10:20|CRITICAL|root|Unhandled exception:Traceback (most recent call last):
  File "C:\Users\RAMAN\workspace\NearField\ScopeFoundry\hardware.py", line 220, in enable_connection
    raise err
  File "C:\Users\RAMAN\workspace\NearField\ScopeFoundry\hardware.py", line 210, in enable_connection
    self.connect()
  File "C:\Users\RAMAN\workspace\NearField\ScopeFoundryHW\aist_nt_remote_spm_rpc\remote_spm_hw.py", line 53, in connect
    remote_spm.setProperty("Ice.ACM.Client", "0")
  File "C:\Users\RAMAN\workspace\NearField\ScopeFoundryHW\aist_nt_remote_spm_rpc\RemoteSpm_ice.py", line 32, in setProperty
    return _M_RemoteSpmRPC.RemoteSpm._op_setProperty.invoke(self, ((prop, val), context))
Ice.OperationNotExistException: exception ::Ice::OperationNotExistException
{
    id = 
    {
        name = myTestAdapter
        category = 
    }
    facet = 
    operation = setProperty
}

2021-12-02T20:10:28|CRITICAL|root|Unhandled exception:Traceback (most recent call last):
  File "C:\Users\RAMAN\workspace\NearField\ScopeFoundry\hardware.py", line 220, in enable_connection
    raise err
  File "C:\Users\RAMAN\workspace\NearField\ScopeFoundry\hardware.py", line 210, in enable_connection
    self.connect()
  File "C:\Users\RAMAN\workspace\NearField\ScopeFoundryHW\aist_nt_remote_spm_rpc\remote_spm_hw.py", line 53, in connect
    remote_spm.setProperty("Ice.ACM.Client", "0")
  File "C:\Users\RAMAN\workspace\NearField\ScopeFoundryHW\aist_nt_remote_spm_rpc\RemoteSpm_ice.py", line 32, in setProperty
    return _M_RemoteSpmRPC.RemoteSpm._op_setProperty.invoke(self, ((prop, val), context))
Ice.OperationNotExistException: exception ::Ice::OperationNotExistException
{
    id = 
    {
        name = myTestAdapter
        category = 
    }
    facet = 
    operation = setProperty
}

2021-12-02T20:10:54|CRITICAL|root|Unhandled exception:Traceback (most recent call last):
  File "C:\Users\RAMAN\workspace\NearField\ScopeFoundry\hardware.py", line 220, in enable_connection
    raise err
  File "C:\Users\RAMAN\workspace\NearField\ScopeFoundry\hardware.py", line 210, in enable_connection
    self.connect()
  File "C:\Users\RAMAN\workspace\NearField\ScopeFoundryHW\aist_nt_remote_spm_rpc\remote_spm_hw.py", line 53, in connect
    remote_spm.setProperty("Ice.ACM.Client", "0")
  File "C:\Users\RAMAN\workspace\NearField\ScopeFoundryHW\aist_nt_remote_spm_rpc\RemoteSpm_ice.py", line 32, in setProperty
    return _M_RemoteSpmRPC.RemoteSpm._op_setProperty.invoke(self, ((prop, val), context))
Ice.OperationNotExistException: exception ::Ice::OperationNotExistException
{
    id = 
    {
        name = myTestAdapter
        category = 
    }
    facet = 
    operation = setProperty
}

2021-12-02T20:11:24|CRITICAL|root|Unhandled exception:Traceback (most recent call last):
  File "C:\Users\RAMAN\workspace\NearField\ScopeFoundry\hardware.py", line 220, in enable_connection
    raise err
  File "C:\Users\RAMAN\workspace\NearField\ScopeFoundry\hardware.py", line 210, in enable_connection
    self.connect()
  File "C:\Users\RAMAN\workspace\NearField\ScopeFoundryHW\aist_nt_remote_spm_rpc\remote_spm_hw.py", line 58, in connect
    remote_spm.setProperty("Ice.ACM.Client", "0")
  File "C:\Users\RAMAN\workspace\NearField\ScopeFoundryHW\aist_nt_remote_spm_rpc\RemoteSpm_ice.py", line 32, in setProperty
    return _M_RemoteSpmRPC.RemoteSpm._op_setProperty.invoke(self, ((prop, val), context))
Ice.OperationNotExistException: exception ::Ice::OperationNotExistException
{
    id = 
    {
        name = myTestAdapter
        category = 
    }
    facet = 
    operation = setProperty
}

2021-12-02T20:12:03|CRITICAL|root|Unhandled exception:Traceback (most recent call last):
  File "C:\Users\RAMAN\workspace\NearField\ScopeFoundry\hardware.py", line 220, in enable_connection
    raise err
  File "C:\Users\RAMAN\workspace\NearField\ScopeFoundry\hardware.py", line 210, in enable_connection
    self.connect()
  File "C:\Users\RAMAN\workspace\NearField\ScopeFoundryHW\aist_nt_remote_spm_rpc\remote_spm_hw.py", line 58, in connect
    remote_spm.setProperty("Ice.ACM.Client", "0")
  File "C:\Users\RAMAN\workspace\NearField\ScopeFoundryHW\aist_nt_remote_spm_rpc\RemoteSpm_ice.py", line 32, in setProperty
    print(prop, val)
Ice.OperationNotExistException: exception ::Ice::OperationNotExistException
{
    id = 
    {
        name = myTestAdapter
        category = 
    }
    facet = 
    operation = setProperty
}

2021-12-02T20:22:31|CRITICAL|root|Unhandled exception:Traceback (most recent call last):
  File "C:\Users\RAMAN\workspace\NearField\ScopeFoundry\hardware.py", line 220, in enable_connection
    raise err
  File "C:\Users\RAMAN\workspace\NearField\ScopeFoundry\hardware.py", line 210, in enable_connection
    self.connect()
  File "C:\Users\RAMAN\workspace\NearField\ScopeFoundryHW\aist_nt_remote_spm_rpc\remote_spm_hw.py", line 58, in connect
    remote_spm.setProperty("Ice.ACM.Client", "0")
  File "C:\Users\RAMAN\workspace\NearField\ScopeFoundryHW\aist_nt_remote_spm_rpc\RemoteSpm_ice.py", line 32, in setProperty
    return _M_RemoteSpmRPC.RemoteSpm._op_setProperty.invoke(self, ((prop, val), context))
Ice.OperationNotExistException: exception ::Ice::OperationNotExistException
{
    id = 
    {
        name = myTestAdapter
        category = 
    }
    facet = 
    operation = setProperty
}

2021-12-02T20:27:56|CRITICAL|root|Unhandled exception:Traceback (most recent call last):
  File "C:\Users\RAMAN\workspace\NearField\ScopeFoundry\hardware.py", line 220, in enable_connection
    raise err
  File "C:\Users\RAMAN\workspace\NearField\ScopeFoundry\hardware.py", line 210, in enable_connection
    self.connect()
  File "C:\Users\RAMAN\workspace\NearField\ScopeFoundryHW\aist_nt_remote_spm_rpc\remote_spm_hw.py", line 58, in connect
    remote_spm.setProperty("Ice.ACM.Client", "0")
  File "C:\Users\RAMAN\workspace\NearField\ScopeFoundryHW\aist_nt_remote_spm_rpc\RemoteSpm_ice.py", line 32, in setProperty
    return _M_RemoteSpmRPC.RemoteSpm._op_setProperty.invoke(self, ((prop, val), context))
Ice.ConnectionRefusedException: Ice.ConnectionRefusedException:
Unknown error

2021-12-02T20:28:10|CRITICAL|root|Unhandled exception:Traceback (most recent call last):
  File "C:\Users\RAMAN\workspace\NearField\ScopeFoundry\hardware.py", line 220, in enable_connection
    raise err
  File "C:\Users\RAMAN\workspace\NearField\ScopeFoundry\hardware.py", line 210, in enable_connection
    self.connect()
  File "C:\Users\RAMAN\workspace\NearField\ScopeFoundryHW\aist_nt_remote_spm_rpc\remote_spm_hw.py", line 58, in connect
    remote_spm.setProperty("Ice.ACM.Client", "0")
  File "C:\Users\RAMAN\workspace\NearField\ScopeFoundryHW\aist_nt_remote_spm_rpc\RemoteSpm_ice.py", line 32, in setProperty
    return _M_RemoteSpmRPC.RemoteSpm._op_setProperty.invoke(self, ((prop, val), context))
Ice.OperationNotExistException: exception ::Ice::OperationNotExistException
{
    id = 
    {
        name = myTestAdapter
        category = 
    }
    facet = 
    operation = setProperty
}

2021-12-03T10:44:21|CRITICAL|root|Unhandled exception:Traceback (most recent call last):
  File "C:\Users\RAMAN\workspace\NearField\ScopeFoundry\hardware.py", line 220, in enable_connection
    raise err
  File "C:\Users\RAMAN\workspace\NearField\ScopeFoundry\hardware.py", line 210, in enable_connection
    self.connect()
  File "C:\Users\RAMAN\workspace\NearField\ScopeFoundryHW\aist_nt_remote_spm_rpc\remote_spm_hw.py", line 56, in connect
    raise RuntimeError(f"{self.name} Invalid proxy")
RuntimeError: remote_spm_hw Invalid proxy

2021-12-03T10:45:04|CRITICAL|root|Unhandled exception:Traceback (most recent call last):
  File "C:\Users\RAMAN\workspace\NearField\ScopeFoundry\hardware.py", line 220, in enable_connection
    raise err
  File "C:\Users\RAMAN\workspace\NearField\ScopeFoundry\hardware.py", line 210, in enable_connection
    self.connect()
  File "C:\Users\RAMAN\workspace\NearField\ScopeFoundryHW\aist_nt_remote_spm_rpc\remote_spm_hw.py", line 53, in connect
    remote_spm.setProperty("Ice.ACM.Client", "0")
AttributeError: 'NoneType' object has no attribute 'setProperty'

2021-12-03T10:45:05|CRITICAL|root|Unhandled exception:Traceback (most recent call last):
  File "C:\Users\RAMAN\workspace\NearField\ScopeFoundry\hardware.py", line 220, in enable_connection
    raise err
  File "C:\Users\RAMAN\workspace\NearField\ScopeFoundry\hardware.py", line 210, in enable_connection
    self.connect()
  File "C:\Users\RAMAN\workspace\NearField\ScopeFoundryHW\aist_nt_remote_spm_rpc\remote_spm_hw.py", line 53, in connect
    remote_spm.setProperty("Ice.ACM.Client", "0")
AttributeError: 'NoneType' object has no attribute 'setProperty'

2021-12-03T10:45:06|CRITICAL|root|Unhandled exception:Traceback (most recent call last):
  File "C:\Users\RAMAN\workspace\NearField\ScopeFoundry\hardware.py", line 220, in enable_connection
    raise err
  File "C:\Users\RAMAN\workspace\NearField\ScopeFoundry\hardware.py", line 210, in enable_connection
    self.connect()
  File "C:\Users\RAMAN\workspace\NearField\ScopeFoundryHW\aist_nt_remote_spm_rpc\remote_spm_hw.py", line 53, in connect
    remote_spm.setProperty("Ice.ACM.Client", "0")
AttributeError: 'NoneType' object has no attribute 'setProperty'

2021-12-03T10:45:32|CRITICAL|root|Unhandled exception:Traceback (most recent call last):
  File "C:\Users\RAMAN\workspace\NearField\ScopeFoundry\hardware.py", line 220, in enable_connection
    raise err
  File "C:\Users\RAMAN\workspace\NearField\ScopeFoundry\hardware.py", line 210, in enable_connection
    self.connect()
  File "C:\Users\RAMAN\workspace\NearField\ScopeFoundryHW\aist_nt_remote_spm_rpc\remote_spm_hw.py", line 51, in connect
    communicator.propertyToProxy('RemoteSpm.Proxy', 'config.client'))
TypeError: propertyToProxy() takes 2 positional arguments but 3 were given

2021-12-03T10:45:50|CRITICAL|root|Unhandled exception:Traceback (most recent call last):
  File "C:\Users\RAMAN\workspace\NearField\ScopeFoundry\hardware.py", line 220, in enable_connection
    raise err
  File "C:\Users\RAMAN\workspace\NearField\ScopeFoundry\hardware.py", line 210, in enable_connection
    self.connect()
  File "C:\Users\RAMAN\workspace\NearField\ScopeFoundryHW\aist_nt_remote_spm_rpc\remote_spm_hw.py", line 55, in connect
    raise RuntimeError(f"{self.name} Invalid proxy")
RuntimeError: remote_spm_hw Invalid proxy

2021-12-03T10:45:52|CRITICAL|root|Unhandled exception:Traceback (most recent call last):
  File "C:\Users\RAMAN\workspace\NearField\ScopeFoundry\hardware.py", line 220, in enable_connection
    raise err
  File "C:\Users\RAMAN\workspace\NearField\ScopeFoundry\hardware.py", line 210, in enable_connection
    self.connect()
  File "C:\Users\RAMAN\workspace\NearField\ScopeFoundryHW\aist_nt_remote_spm_rpc\remote_spm_hw.py", line 55, in connect
    raise RuntimeError(f"{self.name} Invalid proxy")
RuntimeError: remote_spm_hw Invalid proxy

2021-12-03T10:47:21|CRITICAL|root|Unhandled exception:Traceback (most recent call last):
  File "C:\Users\RAMAN\workspace\NearField\ScopeFoundry\hardware.py", line 220, in enable_connection
    raise err
  File "C:\Users\RAMAN\workspace\NearField\ScopeFoundry\hardware.py", line 210, in enable_connection
    self.connect()
  File "C:\Users\RAMAN\workspace\NearField\ScopeFoundryHW\aist_nt_remote_spm_rpc\remote_spm_hw.py", line 52, in connect
    remote_spm.setProperty("Ice.ACM.Client", "0")
  File "C:\Users\RAMAN\workspace\NearField\ScopeFoundryHW\aist_nt_remote_spm_rpc\RemoteSpm_ice.py", line 32, in setProperty
    return _M_RemoteSpmRPC.RemoteSpm._op_setProperty.invoke(self, ((prop, val), context))
Ice.FacetNotExistException: exception ::Ice::FacetNotExistException
{
    id = 
    {
        name = myTestAdapter
        category = 
    }
    facet = config.client
    operation = setProperty
}

2021-12-03T10:47:22|CRITICAL|root|Unhandled exception:Traceback (most recent call last):
  File "C:\Users\RAMAN\workspace\NearField\ScopeFoundry\hardware.py", line 220, in enable_connection
    raise err
  File "C:\Users\RAMAN\workspace\NearField\ScopeFoundry\hardware.py", line 210, in enable_connection
    self.connect()
  File "C:\Users\RAMAN\workspace\NearField\ScopeFoundryHW\aist_nt_remote_spm_rpc\remote_spm_hw.py", line 52, in connect
    remote_spm.setProperty("Ice.ACM.Client", "0")
  File "C:\Users\RAMAN\workspace\NearField\ScopeFoundryHW\aist_nt_remote_spm_rpc\RemoteSpm_ice.py", line 32, in setProperty
    return _M_RemoteSpmRPC.RemoteSpm._op_setProperty.invoke(self, ((prop, val), context))
Ice.FacetNotExistException: exception ::Ice::FacetNotExistException
{
    id = 
    {
        name = myTestAdapter
        category = 
    }
    facet = config.client
    operation = setProperty
}

2021-12-03T10:47:37|CRITICAL|root|Unhandled exception:Traceback (most recent call last):
  File "C:\Users\RAMAN\workspace\NearField\ScopeFoundry\hardware.py", line 220, in enable_connection
    raise err
  File "C:\Users\RAMAN\workspace\NearField\ScopeFoundry\hardware.py", line 210, in enable_connection
    self.connect()
  File "C:\Users\RAMAN\workspace\NearField\ScopeFoundryHW\aist_nt_remote_spm_rpc\remote_spm_hw.py", line 44, in connect
    base = communicator.propertyToProxy('RemoteSpm.Proxy')
  File "C:\ProgramData\Anaconda3\lib\site-packages\Ice\__init__.py", line 918, in propertyToProxy
    return self._impl.propertyToProxy(str)
Ice.EndpointParseException: exception ::Ice::EndpointParseException
{
    str = unrecognized argument `-localhost' in endpoint `default -p 54321 -localhost'
}

2021-12-03T10:47:45|CRITICAL|root|Unhandled exception:Traceback (most recent call last):
  File "C:\Users\RAMAN\workspace\NearField\ScopeFoundry\hardware.py", line 220, in enable_connection
    raise err
  File "C:\Users\RAMAN\workspace\NearField\ScopeFoundry\hardware.py", line 210, in enable_connection
    self.connect()
  File "C:\Users\RAMAN\workspace\NearField\ScopeFoundryHW\aist_nt_remote_spm_rpc\remote_spm_hw.py", line 44, in connect
    base = communicator.propertyToProxy('RemoteSpm.Proxy')
  File "C:\ProgramData\Anaconda3\lib\site-packages\Ice\__init__.py", line 918, in propertyToProxy
    return self._impl.propertyToProxy(str)
Ice.EndpointParseException: exception ::Ice::EndpointParseException
{
    str = unrecognized argument `localhost' in endpoint `default -p 54321 localhost'
}

2021-12-03T10:47:54|CRITICAL|root|Unhandled exception:Traceback (most recent call last):
  File "C:\Users\RAMAN\workspace\NearField\ScopeFoundry\hardware.py", line 220, in enable_connection
    raise err
  File "C:\Users\RAMAN\workspace\NearField\ScopeFoundry\hardware.py", line 210, in enable_connection
    self.connect()
  File "C:\Users\RAMAN\workspace\NearField\ScopeFoundryHW\aist_nt_remote_spm_rpc\remote_spm_hw.py", line 52, in connect
    remote_spm.setProperty("Ice.ACM.Client", "0")
  File "C:\Users\RAMAN\workspace\NearField\ScopeFoundryHW\aist_nt_remote_spm_rpc\RemoteSpm_ice.py", line 32, in setProperty
    return _M_RemoteSpmRPC.RemoteSpm._op_setProperty.invoke(self, ((prop, val), context))
Ice.FacetNotExistException: exception ::Ice::FacetNotExistException
{
    id = 
    {
        name = myTestAdapter
        category = 
    }
    facet = config.client
    operation = setProperty
}

2021-12-03T10:48:45|CRITICAL|root|Unhandled exception:Traceback (most recent call last):
  File "C:\Users\RAMAN\workspace\NearField\ScopeFoundry\hardware.py", line 220, in enable_connection
    raise err
  File "C:\Users\RAMAN\workspace\NearField\ScopeFoundry\hardware.py", line 210, in enable_connection
    self.connect()
  File "C:\Users\RAMAN\workspace\NearField\ScopeFoundryHW\aist_nt_remote_spm_rpc\remote_spm_hw.py", line 53, in connect
    print(remote_spm.isConnected())
  File "C:\Users\RAMAN\workspace\NearField\ScopeFoundryHW\aist_nt_remote_spm_rpc\RemoteSpm_ice.py", line 128, in isConnected
    return _M_RemoteSpmRPC.RemoteSpm._op_isConnected.invoke(self, ((), context))
Ice.FacetNotExistException: exception ::Ice::FacetNotExistException
{
    id = 
    {
        name = myTestAdapter
        category = 
    }
    facet = config.client
    operation = isConnected
}

2021-12-03T10:51:07|CRITICAL|root|Unhandled exception:Traceback (most recent call last):
  File "C:\Users\RAMAN\workspace\NearField\ScopeFoundry\hardware.py", line 220, in enable_connection
    raise err
  File "C:\Users\RAMAN\workspace\NearField\ScopeFoundry\hardware.py", line 210, in enable_connection
    self.connect()
  File "C:\Users\RAMAN\workspace\NearField\ScopeFoundryHW\aist_nt_remote_spm_rpc\remote_spm_hw.py", line 52, in connect
    print(remote_spm.isConnected())
  File "C:\Users\RAMAN\workspace\NearField\ScopeFoundryHW\aist_nt_remote_spm_rpc\RemoteSpm_ice.py", line 128, in isConnected
    return _M_RemoteSpmRPC.RemoteSpm._op_isConnected.invoke(self, ((), context))
Ice.FacetNotExistException: exception ::Ice::FacetNotExistException
{
    id = 
    {
        name = myTestAdapter
        category = 
    }
    facet = config.client
    operation = isConnected
}

2021-12-03T10:51:29|CRITICAL|root|Unhandled exception:Traceback (most recent call last):
  File "C:\Users\RAMAN\workspace\NearField\ScopeFoundry\hardware.py", line 220, in enable_connection
    raise err
  File "C:\Users\RAMAN\workspace\NearField\ScopeFoundry\hardware.py", line 210, in enable_connection
    self.connect()
  File "C:\Users\RAMAN\workspace\NearField\ScopeFoundryHW\aist_nt_remote_spm_rpc\remote_spm_hw.py", line 49, in connect
    raise RuntimeError(f"{self.name} Invalid proxy")
RuntimeError: remote_spm_hw Invalid proxy

2021-12-03T10:52:05|CRITICAL|root|Unhandled exception:Traceback (most recent call last):
  File "C:\Users\RAMAN\workspace\NearField\ScopeFoundry\hardware.py", line 220, in enable_connection
    raise err
  File "C:\Users\RAMAN\workspace\NearField\ScopeFoundry\hardware.py", line 210, in enable_connection
    self.connect()
  File "C:\Users\RAMAN\workspace\NearField\ScopeFoundryHW\aist_nt_remote_spm_rpc\remote_spm_hw.py", line 49, in connect
    raise RuntimeError(f"{self.name} Invalid proxy")
RuntimeError: remote_spm_hw Invalid proxy

2021-12-03T10:52:40|CRITICAL|root|Unhandled exception:Traceback (most recent call last):
  File "C:\Users\RAMAN\workspace\NearField\ScopeFoundry\hardware.py", line 220, in enable_connection
    raise err
  File "C:\Users\RAMAN\workspace\NearField\ScopeFoundry\hardware.py", line 210, in enable_connection
    self.connect()
  File "C:\Users\RAMAN\workspace\NearField\ScopeFoundryHW\aist_nt_remote_spm_rpc\remote_spm_hw.py", line 50, in connect
    raise RuntimeError(f"{self.name} Invalid proxy")
RuntimeError: remote_spm_hw Invalid proxy

2021-12-03T10:52:59|CRITICAL|root|Unhandled exception:Traceback (most recent call last):
  File "C:\Users\RAMAN\workspace\NearField\ScopeFoundry\hardware.py", line 220, in enable_connection
    raise err
  File "C:\Users\RAMAN\workspace\NearField\ScopeFoundry\hardware.py", line 210, in enable_connection
    self.connect()
  File "C:\Users\RAMAN\workspace\NearField\ScopeFoundryHW\aist_nt_remote_spm_rpc\remote_spm_hw.py", line 48, in connect
    print(remote_spm.isConnected())
AttributeError: 'NoneType' object has no attribute 'isConnected'

2021-12-03T10:53:10|CRITICAL|root|Unhandled exception:Traceback (most recent call last):
  File "C:\Users\RAMAN\workspace\NearField\ScopeFoundry\hardware.py", line 220, in enable_connection
    raise err
  File "C:\Users\RAMAN\workspace\NearField\ScopeFoundry\hardware.py", line 210, in enable_connection
    self.connect()
  File "C:\Users\RAMAN\workspace\NearField\ScopeFoundryHW\aist_nt_remote_spm_rpc\remote_spm_hw.py", line 48, in connect
    print(remote_spm.isConnected())
  File "C:\Users\RAMAN\workspace\NearField\ScopeFoundryHW\aist_nt_remote_spm_rpc\RemoteSpm_ice.py", line 128, in isConnected
    return _M_RemoteSpmRPC.RemoteSpm._op_isConnected.invoke(self, ((), context))
Ice.FacetNotExistException: exception ::Ice::FacetNotExistException
{
    id = 
    {
        name = myTestAdapter
        category = 
    }
    facet = config.client
    operation = isConnected
}

2021-12-03T10:53:41|CRITICAL|root|Unhandled exception:Traceback (most recent call last):
  File "C:\Users\RAMAN\workspace\NearField\ScopeFoundry\hardware.py", line 220, in enable_connection
    raise err
  File "C:\Users\RAMAN\workspace\NearField\ScopeFoundry\hardware.py", line 210, in enable_connection
    self.connect()
  File "C:\Users\RAMAN\workspace\NearField\ScopeFoundryHW\aist_nt_remote_spm_rpc\remote_spm_hw.py", line 48, in connect
    print(remote_spm.isConnected())
  File "C:\Users\RAMAN\workspace\NearField\ScopeFoundryHW\aist_nt_remote_spm_rpc\RemoteSpm_ice.py", line 128, in isConnected
    return _M_RemoteSpmRPC.RemoteSpm._op_isConnected.invoke(self, ((), context))
Ice.FacetNotExistException: exception ::Ice::FacetNotExistException
{
    id = 
    {
        name = myTestAdapter
        category = 
    }
    facet = config.client
    operation = isConnected
}

2021-12-03T10:54:00|CRITICAL|root|Unhandled exception:Traceback (most recent call last):
  File "C:\Users\RAMAN\workspace\NearField\ScopeFoundry\hardware.py", line 220, in enable_connection
    raise err
  File "C:\Users\RAMAN\workspace\NearField\ScopeFoundry\hardware.py", line 210, in enable_connection
    self.connect()
  File "C:\Users\RAMAN\workspace\NearField\ScopeFoundryHW\aist_nt_remote_spm_rpc\remote_spm_hw.py", line 44, in connect
    base = communicator.propertyToProxy('RemoteSpm.Proxy')
  File "C:\ProgramData\Anaconda3\lib\site-packages\Ice\__init__.py", line 918, in propertyToProxy
    return self._impl.propertyToProxy(str)
Ice.EndpointParseException: exception ::Ice::EndpointParseException
{
    str = invalid endpoint `ssl -p 54321' in `myTestAdapter -e 1.0:ssl -p 54321'
}

2021-12-03T10:54:14|CRITICAL|root|Unhandled exception:Traceback (most recent call last):
  File "C:\Users\RAMAN\workspace\NearField\ScopeFoundry\hardware.py", line 220, in enable_connection
    raise err
  File "C:\Users\RAMAN\workspace\NearField\ScopeFoundry\hardware.py", line 210, in enable_connection
    self.connect()
  File "C:\Users\RAMAN\workspace\NearField\ScopeFoundryHW\aist_nt_remote_spm_rpc\remote_spm_hw.py", line 44, in connect
    base = communicator.propertyToProxy('RemoteSpm.Proxy')
  File "C:\ProgramData\Anaconda3\lib\site-packages\Ice\__init__.py", line 918, in propertyToProxy
    return self._impl.propertyToProxy(str)
Ice.EndpointParseException: exception ::Ice::EndpointParseException
{
    str = invalid endpoint `sll -p 54321' in `myTestAdapter -e 1.0:sll -p 54321'
}

2021-12-03T10:54:39|CRITICAL|root|Unhandled exception:Traceback (most recent call last):
  File "C:\Users\RAMAN\workspace\NearField\ScopeFoundry\hardware.py", line 220, in enable_connection
    raise err
  File "C:\Users\RAMAN\workspace\NearField\ScopeFoundry\hardware.py", line 210, in enable_connection
    self.connect()
  File "C:\Users\RAMAN\workspace\NearField\ScopeFoundryHW\aist_nt_remote_spm_rpc\remote_spm_hw.py", line 48, in connect
    print(remote_spm.isConnected())
  File "C:\Users\RAMAN\workspace\NearField\ScopeFoundryHW\aist_nt_remote_spm_rpc\RemoteSpm_ice.py", line 128, in isConnected
    return _M_RemoteSpmRPC.RemoteSpm._op_isConnected.invoke(self, ((), context))
Ice.FacetNotExistException: exception ::Ice::FacetNotExistException
{
    id = 
    {
        name = myTestAdapter
        category = 
    }
    facet = config.client
    operation = isConnected
}

2021-12-03T10:57:46|CRITICAL|root|Unhandled exception:Traceback (most recent call last):
  File "C:\Users\RAMAN\workspace\NearField\ScopeFoundry\hardware.py", line 220, in enable_connection
    raise err
  File "C:\Users\RAMAN\workspace\NearField\ScopeFoundry\hardware.py", line 210, in enable_connection
    self.connect()
  File "C:\Users\RAMAN\workspace\NearField\ScopeFoundryHW\aist_nt_remote_spm_rpc\remote_spm_hw.py", line 42, in connect
    Ice.loadSlice('RemoteSpm2.ice')
RuntimeError: Slice preprocessing failed for `RemoteSpm2.ice'

