2021-12-02T19:44:48|CRITICAL|root|Unhandled exception:Traceback (most recent call last):
  File "C:\Users\RAMAN\workspace\NearField\ScopeFoundry\hardware.py", line 220, in enable_connection
    raise err
  File "C:\Users\RAMAN\workspace\NearField\ScopeFoundry\hardware.py", line 210, in enable_connection
    self.connect()
  File "C:\Users\RAMAN\workspace\NearField\ScopeFoundryHW\aist_nt_remote_spm_rpc\remote_spm_hw.py", line 53, in connect
    remote_spm.setProperty("Ice.ACM.Client", "0")
  File "C:\Users\RAMAN\workspace\NearField\ScopeFoundryHW\aist_nt_remote_spm_rpc\RemoteSpm_ice.py", line 31, in setProperty
    return _M_RemoteSpmRPC.RemoteSpm._op_setProperty.invoke(self, ((prop, val), context))
Ice.OperationNotExistException: exception ::Ice::OperationNotExistException
{
    id = 
    {
        name = myTestAdapter
        category = 
    }
    facet = 
    operation = setProperty
}

2021-12-02T19:45:09|CRITICAL|root|Unhandled exception:Traceback (most recent call last):
  File "C:\Users\RAMAN\workspace\NearField\ScopeFoundry\hardware.py", line 220, in enable_connection
    raise err
  File "C:\Users\RAMAN\workspace\NearField\ScopeFoundry\hardware.py", line 210, in enable_connection
    self.connect()
  File "C:\Users\RAMAN\workspace\NearField\ScopeFoundryHW\aist_nt_remote_spm_rpc\remote_spm_hw.py", line 54, in connect
    remote_spm.start()
  File "C:\Users\RAMAN\workspace\NearField\ScopeFoundryHW\aist_nt_remote_spm_rpc\RemoteSpm_ice.py", line 55, in start
    return _M_RemoteSpmRPC.RemoteSpm._op_start.invoke(self, ((), context))
Ice.OperationNotExistException: exception ::Ice::OperationNotExistException
{
    id = 
    {
        name = myTestAdapter
        category = 
    }
    facet = 
    operation = start
}

2021-12-02T19:45:35|CRITICAL|root|Unhandled exception:Traceback (most recent call last):
  File "C:\Users\RAMAN\workspace\NearField\ScopeFoundry\hardware.py", line 220, in enable_connection
    raise err
  File "C:\Users\RAMAN\workspace\NearField\ScopeFoundry\hardware.py", line 210, in enable_connection
    self.connect()
  File "C:\Users\RAMAN\workspace\NearField\ScopeFoundryHW\aist_nt_remote_spm_rpc\remote_spm_hw.py", line 55, in connect
    remote_spm.start()
  File "C:\Users\RAMAN\workspace\NearField\ScopeFoundryHW\aist_nt_remote_spm_rpc\RemoteSpm_ice.py", line 55, in start
    return _M_RemoteSpmRPC.RemoteSpm._op_start.invoke(self, ((), context))
Ice.OperationNotExistException: exception ::Ice::OperationNotExistException
{
    id = 
    {
        name = myTestAdapter
        category = 
    }
    facet = 
    operation = start
}

2021-12-02T19:45:43|CRITICAL|root|Unhandled exception:Traceback (most recent call last):
  File "C:\Users\RAMAN\workspace\NearField\ScopeFoundry\hardware.py", line 220, in enable_connection
    raise err
  File "C:\Users\RAMAN\workspace\NearField\ScopeFoundry\hardware.py", line 210, in enable_connection
    self.connect()
  File "C:\Users\RAMAN\workspace\NearField\ScopeFoundryHW\aist_nt_remote_spm_rpc\remote_spm_hw.py", line 55, in connect
    remote_spm.start()
  File "C:\Users\RAMAN\workspace\NearField\ScopeFoundryHW\aist_nt_remote_spm_rpc\RemoteSpm_ice.py", line 55, in start
    return _M_RemoteSpmRPC.RemoteSpm._op_start.invoke(self, ((), context))
Ice.OperationNotExistException: exception ::Ice::OperationNotExistException
{
    id = 
    {
        name = myTestAdapter
        category = 
    }
    facet = 
    operation = start
}

2021-12-02T19:46:01|CRITICAL|root|Unhandled exception:Traceback (most recent call last):
  File "C:\Users\RAMAN\workspace\NearField\ScopeFoundry\hardware.py", line 220, in enable_connection
    raise err
  File "C:\Users\RAMAN\workspace\NearField\ScopeFoundry\hardware.py", line 210, in enable_connection
    self.connect()
  File "C:\Users\RAMAN\workspace\NearField\ScopeFoundryHW\aist_nt_remote_spm_rpc\remote_spm_hw.py", line 55, in connect
    remote_spm.start()
  File "C:\Users\RAMAN\workspace\NearField\ScopeFoundryHW\aist_nt_remote_spm_rpc\RemoteSpm_ice.py", line 55, in start
    return _M_RemoteSpmRPC.RemoteSpm._op_start.invoke(self, ((), context))
Ice.OperationNotExistException: exception ::Ice::OperationNotExistException
{
    id = 
    {
        name = myTestAdapter
        category = 
    }
    facet = 
    operation = start
}

2021-12-02T19:47:52|CRITICAL|root|Unhandled exception:Traceback (most recent call last):
  File "C:\Users\RAMAN\workspace\NearField\ScopeFoundry\hardware.py", line 220, in enable_connection
    raise err
  File "C:\Users\RAMAN\workspace\NearField\ScopeFoundry\hardware.py", line 210, in enable_connection
    self.connect()
  File "C:\Users\RAMAN\workspace\NearField\ScopeFoundryHW\aist_nt_remote_spm_rpc\remote_spm_hw.py", line 55, in connect
    remote_spm.start()
  File "C:\Users\RAMAN\workspace\NearField\ScopeFoundryHW\aist_nt_remote_spm_rpc\RemoteSpm_ice.py", line 55, in start
    def start(self, context=None):
Ice.OperationNotExistException: exception ::Ice::OperationNotExistException
{
    id = 
    {
        name = myTestAdapter
        category = 
    }
    facet = 
    operation = start
}

2021-12-02T19:48:03|CRITICAL|root|Unhandled exception:Traceback (most recent call last):
  File "C:\Users\RAMAN\workspace\NearField\ScopeFoundry\hardware.py", line 220, in enable_connection
    raise err
  File "C:\Users\RAMAN\workspace\NearField\ScopeFoundry\hardware.py", line 210, in enable_connection
    self.connect()
  File "C:\Users\RAMAN\workspace\NearField\ScopeFoundryHW\aist_nt_remote_spm_rpc\remote_spm_hw.py", line 55, in connect
    remote_spm.start()
  File "C:\Users\RAMAN\workspace\NearField\ScopeFoundryHW\aist_nt_remote_spm_rpc\RemoteSpm_ice.py", line 55, in start
    def start(self, context=None):
Ice.OperationNotExistException: exception ::Ice::OperationNotExistException
{
    id = 
    {
        name = myTestAdapter
        category = 
    }
    facet = 
    operation = start
}

2021-12-02T19:52:48|CRITICAL|root|Unhandled exception:Traceback (most recent call last):
  File "C:\Users\RAMAN\workspace\NearField\ScopeFoundry\hardware.py", line 220, in enable_connection
    raise err
  File "C:\Users\RAMAN\workspace\NearField\ScopeFoundry\hardware.py", line 210, in enable_connection
    self.connect()
  File "C:\Users\RAMAN\workspace\NearField\ScopeFoundryHW\aist_nt_remote_spm_rpc\remote_spm_hw.py", line 52, in connect
    raise RuntimeError(f"{self.name} Invalid proxy")
RuntimeError: remote_spm_hw Invalid proxy

2021-12-02T19:52:50|CRITICAL|root|Unhandled exception:Traceback (most recent call last):
  File "C:\Users\RAMAN\workspace\NearField\ScopeFoundry\hardware.py", line 220, in enable_connection
    raise err
  File "C:\Users\RAMAN\workspace\NearField\ScopeFoundry\hardware.py", line 210, in enable_connection
    self.connect()
  File "C:\Users\RAMAN\workspace\NearField\ScopeFoundryHW\aist_nt_remote_spm_rpc\remote_spm_hw.py", line 52, in connect
    raise RuntimeError(f"{self.name} Invalid proxy")
RuntimeError: remote_spm_hw Invalid proxy

2021-12-02T19:52:50|CRITICAL|root|Unhandled exception:Traceback (most recent call last):
  File "C:\Users\RAMAN\workspace\NearField\ScopeFoundry\hardware.py", line 220, in enable_connection
    raise err
  File "C:\Users\RAMAN\workspace\NearField\ScopeFoundry\hardware.py", line 210, in enable_connection
    self.connect()
  File "C:\Users\RAMAN\workspace\NearField\ScopeFoundryHW\aist_nt_remote_spm_rpc\remote_spm_hw.py", line 52, in connect
    raise RuntimeError(f"{self.name} Invalid proxy")
RuntimeError: remote_spm_hw Invalid proxy

2021-12-02T19:52:53|CRITICAL|root|Unhandled exception:Traceback (most recent call last):
  File "C:\Users\RAMAN\workspace\NearField\ScopeFoundry\hardware.py", line 220, in enable_connection
    raise err
  File "C:\Users\RAMAN\workspace\NearField\ScopeFoundry\hardware.py", line 210, in enable_connection
    self.connect()
  File "C:\Users\RAMAN\workspace\NearField\ScopeFoundryHW\aist_nt_remote_spm_rpc\remote_spm_hw.py", line 52, in connect
    raise RuntimeError(f"{self.name} Invalid proxy")
RuntimeError: remote_spm_hw Invalid proxy

2021-12-02T19:54:27|CRITICAL|root|Unhandled exception:Traceback (most recent call last):
  File "C:\Users\RAMAN\workspace\NearField\ScopeFoundry\hardware.py", line 220, in enable_connection
    raise err
  File "C:\Users\RAMAN\workspace\NearField\ScopeFoundry\hardware.py", line 210, in enable_connection
    self.connect()
  File "C:\Users\RAMAN\workspace\NearField\ScopeFoundryHW\aist_nt_remote_spm_rpc\remote_spm_hw.py", line 52, in connect
    raise RuntimeError(f"{self.name} Invalid proxy")
RuntimeError: remote_spm_hw Invalid proxy

2021-12-02T19:54:42|CRITICAL|root|Unhandled exception:Traceback (most recent call last):
  File "C:\Users\RAMAN\workspace\NearField\ScopeFoundry\hardware.py", line 220, in enable_connection
    raise err
  File "C:\Users\RAMAN\workspace\NearField\ScopeFoundry\hardware.py", line 210, in enable_connection
    self.connect()
  File "C:\Users\RAMAN\workspace\NearField\ScopeFoundryHW\aist_nt_remote_spm_rpc\remote_spm_hw.py", line 52, in connect
    raise RuntimeError(f"{self.name} Invalid proxy")
RuntimeError: remote_spm_hw Invalid proxy

2021-12-02T19:54:51|CRITICAL|root|Unhandled exception:Traceback (most recent call last):
  File "C:\Users\RAMAN\workspace\NearField\ScopeFoundry\hardware.py", line 220, in enable_connection
    raise err
  File "C:\Users\RAMAN\workspace\NearField\ScopeFoundry\hardware.py", line 210, in enable_connection
    self.connect()
  File "C:\Users\RAMAN\workspace\NearField\ScopeFoundryHW\aist_nt_remote_spm_rpc\remote_spm_hw.py", line 52, in connect
    raise RuntimeError(f"{self.name} Invalid proxy")
RuntimeError: remote_spm_hw Invalid proxy

2021-12-02T19:55:02|CRITICAL|root|Unhandled exception:Traceback (most recent call last):
  File "C:\Users\RAMAN\workspace\NearField\ScopeFoundry\hardware.py", line 220, in enable_connection
    raise err
  File "C:\Users\RAMAN\workspace\NearField\ScopeFoundry\hardware.py", line 210, in enable_connection
    self.connect()
  File "C:\Users\RAMAN\workspace\NearField\ScopeFoundryHW\aist_nt_remote_spm_rpc\remote_spm_hw.py", line 52, in connect
    raise RuntimeError(f"{self.name} Invalid proxy")
RuntimeError: remote_spm_hw Invalid proxy

