2021-12-02T19:47:55|CRITICAL|root|Unhandled exception:Traceback (most recent call last):
  File "C:\Users\RAMAN\workspace\NearField\ScopeFoundry\hardware.py", line 220, in enable_connection
    raise err
  File "C:\Users\RAMAN\workspace\NearField\ScopeFoundry\hardware.py", line 210, in enable_connection
    self.connect()
  File "C:\Users\RAMAN\workspace\NearField\ScopeFoundryHW\aist_nt_remote_spm_rpc\remote_spm_hw.py", line 55, in connect
    remote_spm.start()
  File "C:\Users\RAMAN\workspace\NearField\ScopeFoundryHW\aist_nt_remote_spm_rpc\RemoteSpm_ice.py", line 56, in start
    return _M_RemoteSpmRPC.RemoteSpm._op_start.invoke(self, ((), context))
Ice.OperationNotExistException: exception ::Ice::OperationNotExistException
{
    id = 
    {
        name = myTestAdapter
        category = 
    }
    facet = 
    operation = start
}

