2022-02-03T17:04:47|INFO|PowerScanMeasure|power_scan start_stop False
2022-02-03T17:04:47|INFO|PowerScanMeasure|measurement power_scan stopping stop_first
2022-02-03T17:04:47|INFO|PowerMeterOptimizerMeasure|powermeter_optimizer start_stop False
2022-02-03T17:04:47|INFO|PowerMeterOptimizerMeasure|measurement powermeter_optimizer stopping stop_first
2022-02-03T17:04:47|INFO|DiamondMicroscope|setting up figures for power_scan measurement power_scan
2022-02-03T17:04:47|INFO|PowerScanMeasure|power_scan start_stop False
2022-02-03T17:04:47|INFO|PowerScanMeasure|measurement power_scan stopping stop_first
2022-02-03T17:04:47|INFO|DiamondMicroscope|setting up figures for powermeter_optimizer measurement powermeter_optimizer
2022-02-03T17:04:47|INFO|PowerMeterOptimizerMeasure|powermeter_optimizer start_stop False
2022-02-03T17:04:47|INFO|PowerMeterOptimizerMeasure|measurement powermeter_optimizer stopping stop_first
2022-02-03T17:05:28|DEBUG|FileLQ|save_dir qLineEdit on_edit_finished
2022-02-03T17:05:28|DEBUG|FileLQ|save_dir: update_value 'C:\\Users\\MT-User\\eclipse-workspace\\scope_foundry\\diamond_microscope\\data' --> 'C:\\Users\\MT-User\\eclipse-workspace\\scope_foundry\\diamond_microscope'    sender=<PyQt5.QtWidgets.QLineEdit object at 0x06B965D0>
2022-02-03T17:05:28|DEBUG|FileLQ|save_dir: different values C:\Users\MT-User\eclipse-workspace\scope_foundry\diamond_microscope\data C:\Users\MT-User\eclipse-workspace\scope_foundry\diamond_microscope
2022-02-03T17:05:28|CRITICAL|root|Unhandled exception:Traceback (most recent call last):
  File "C:\Users\MT-User\eclipse-workspace\scope_foundry\ScopeFoundry\hardware.py", line 220, in enable_connection
    raise err
  File "C:\Users\MT-User\eclipse-workspace\scope_foundry\ScopeFoundry\hardware.py", line 210, in enable_connection
    self.connect()
  File "C:\Users\MT-User\eclipse-workspace\scope_foundry\ScopeFoundryHW\thorlabs_powermeter\thorlabs_powermeter.py", line 52, in connect
    from .thorlabs_pm100d import ThorlabsPM100D
  File "C:\Users\MT-User\eclipse-workspace\scope_foundry\ScopeFoundryHW\thorlabs_powermeter\thorlabs_pm100d.py", line 2, in <module>
    import visa
ModuleNotFoundError: No module named 'visa'

2022-02-03T17:05:29|CRITICAL|root|Unhandled exception:Traceback (most recent call last):
  File "C:\Users\MT-User\eclipse-workspace\scope_foundry\ScopeFoundry\hardware.py", line 220, in enable_connection
    raise err
  File "C:\Users\MT-User\eclipse-workspace\scope_foundry\ScopeFoundry\hardware.py", line 210, in enable_connection
    self.connect()
  File "C:\Users\MT-User\eclipse-workspace\scope_foundry\ScopeFoundryHW\thorlabs_powermeter\thorlabs_powermeter.py", line 52, in connect
    from .thorlabs_pm100d import ThorlabsPM100D
  File "C:\Users\MT-User\eclipse-workspace\scope_foundry\ScopeFoundryHW\thorlabs_powermeter\thorlabs_pm100d.py", line 2, in <module>
    import visa
ModuleNotFoundError: No module named 'visa'

2022-02-03T17:05:30|CRITICAL|root|Unhandled exception:Traceback (most recent call last):
  File "C:\Users\MT-User\eclipse-workspace\scope_foundry\ScopeFoundry\hardware.py", line 220, in enable_connection
    raise err
  File "C:\Users\MT-User\eclipse-workspace\scope_foundry\ScopeFoundry\hardware.py", line 210, in enable_connection
    self.connect()
  File "C:\Users\MT-User\eclipse-workspace\scope_foundry\ScopeFoundryHW\thorlabs_powermeter\thorlabs_powermeter.py", line 52, in connect
    from .thorlabs_pm100d import ThorlabsPM100D
  File "C:\Users\MT-User\eclipse-workspace\scope_foundry\ScopeFoundryHW\thorlabs_powermeter\thorlabs_pm100d.py", line 2, in <module>
    import visa
ModuleNotFoundError: No module named 'visa'

2022-02-03T17:07:49|DEBUG|root|close
2022-02-03T17:07:51|DEBUG|root|closing
2022-02-03T17:07:51|INFO|DiamondMicroscope|on_close
2022-02-03T17:07:51|INFO|DiamondMicroscope|disconnecting hydraharp
2022-02-03T17:07:51|INFO|DiamondMicroscope|disconnecting thorlabs_powermeter
2022-02-03T17:07:51|INFO|DiamondMicroscope|disconnecting motorized_polarizer
