2020-12-03T13:35:52|CRITICAL|root|Unhandled exception:Traceback (most recent call last):
  File "C:\Users\lab\Documents\foundry_scope\ScopeFoundry\hardware.py", line 228, in enable_connection
    self.tree_item.setText(1,'X')
AttributeError: 'AttoCubeXYZStageHW' object has no attribute 'tree_item'

During handling of the above exception, another exception occurred:

Traceback (most recent call last):
  File "C:\Users\lab\Documents\foundry_scope\ScopeFoundry\hardware.py", line 232, in enable_connection
    self.tree_item.setText(1,'?')
AttributeError: 'AttoCubeXYZStageHW' object has no attribute 'tree_item'

2020-12-03T13:35:52|INFO|AttoCubeStageControlMeasure|attocube_dev1 start_stop False
2020-12-03T13:35:52|INFO|AttoCubeStageControlMeasure|measurement attocube_dev1 stopping stop_first
2020-12-03T13:35:52|CRITICAL|root|Unhandled exception:Traceback (most recent call last):
  File "C:\Users\lab\.p2\pool\plugins\org.python.pydev.core_7.2.1.201904261721\pysrc\pydevd.py", line 2316, in <module>
    main()
  File "C:\Users\lab\.p2\pool\plugins\org.python.pydev.core_7.2.1.201904261721\pysrc\pydevd.py", line 2309, in main
    globals = debugger.run(setup['file'], None, None, is_module)
  File "C:\Users\lab\.p2\pool\plugins\org.python.pydev.core_7.2.1.201904261721\pysrc\pydevd.py", line 1642, in run
    return self._exec(is_module, entry_point_fn, module_name, file, globals, locals)
  File "C:\Users\lab\.p2\pool\plugins\org.python.pydev.core_7.2.1.201904261721\pysrc\pydevd.py", line 1649, in _exec
    pydev_imports.execfile(file, globals, locals)  # execute the script
  File "C:\Users\lab\.p2\pool\plugins\org.python.pydev.core_7.2.1.201904261721\pysrc\_pydev_imps\_pydev_execfile.py", line 25, in execfile
    exec(compile(contents+"\n", file, 'exec'), glob, loc)
  File "C:\Users\lab\Documents\foundry_scope\ScopeFoundryHW\attocube_ecc100\attocube_test_app.py", line 35, in <module>
    app = AttocubeTestApp(sys.argv)
  File "C:\Users\lab\Documents\foundry_scope\ScopeFoundry\base_app.py", line 338, in __init__
    self.setup()
  File "C:\Users\lab\Documents\foundry_scope\ScopeFoundryHW\attocube_ecc100\attocube_test_app.py", line 25, in setup
    self.add_measurement(AttoCubeStageControlMeasure(self, name='attocube_dev1'))
  File "C:\Users\lab\Documents\foundry_scope\ScopeFoundryHW\attocube_ecc100\attocube_stage_control.py", line 15, in __init__
    Measurement.__init__(self, app, name=name)
  File "C:\Users\lab\Documents\foundry_scope\ScopeFoundry\measurement.py", line 106, in __init__
    self.setup()
  File "C:\Users\lab\Documents\foundry_scope\ScopeFoundryHW\attocube_ecc100\attocube_stage_control.py", line 64, in setup
    func = self.hw.operations[axis + "_jog_"+sign]
KeyError: 'x_jog_p'

