2018-03-06T13:12:24|CRITICAL|root|Unhandled exception:Traceback (most recent call last):
  File "C:\Users\lab\Documents\foundry_scope\ScopeFoundry\hardware.py", line 196, in enable_connection
    self.connect()
  File "C:\Users\lab\Documents\foundry_scope\ScopeFoundryHW\thorlabs_stepper_motors\thorlabs_stepper_controller_hw.py", line 72, in connect
    debug=S['debug_mode'])
  File "C:\Users\lab\Documents\foundry_scope\ScopeFoundryHW\thorlabs_stepper_motors\thorlabs_stepper_controller_dev.py", line 111, in __init__
    self._id = self._serial_numbers[dev_num]
IndexError: list index out of range

2018-03-06T13:16:37|CRITICAL|root|Unhandled exception:Traceback (most recent call last):
  File "C:\Users\lab\Documents\foundry_scope\ScopeFoundry\hardware.py", line 196, in enable_connection
    self.connect()
  File "C:\Users\lab\Documents\foundry_scope\ScopeFoundryHW\thorlabs_stepper_motors\thorlabs_stepper_controller_hw.py", line 72, in connect
    debug=S['debug_mode'])
  File "C:\Users\lab\Documents\foundry_scope\ScopeFoundryHW\thorlabs_stepper_motors\thorlabs_stepper_controller_dev.py", line 121, in __init__
    _err(S.SBC_Open(self._id))
  File "C:\Users\lab\Documents\foundry_scope\ScopeFoundryHW\thorlabs_stepper_motors\thorlabs_stepper_controller_dev.py", line 65, in _err
    raise IOError("Thorlabs Kinesis Error [{}] {}: {} ".format(retval, err_name, description))
OSError: Thorlabs Kinesis Error [3] FT_DeviceNotOpened: The Device must be opened before it can be accessed. See the appropriate Open function for your device. 

2018-03-06T13:19:37|CRITICAL|root|Unhandled exception:Traceback (most recent call last):
  File "C:\Users\lab\Documents\foundry_scope\ScopeFoundry\hardware.py", line 196, in enable_connection
    self.connect()
  File "C:\Users\lab\Documents\foundry_scope\ScopeFoundryHW\thorlabs_stepper_motors\thorlabs_stepper_controller_hw.py", line 72, in connect
    debug=S['debug_mode'])
  File "C:\Users\lab\Documents\foundry_scope\ScopeFoundryHW\thorlabs_stepper_motors\thorlabs_stepper_controller_dev.py", line 121, in __init__
    _err(S.SBC_Open(self._id))
  File "C:\Users\lab\Documents\foundry_scope\ScopeFoundryHW\thorlabs_stepper_motors\thorlabs_stepper_controller_dev.py", line 65, in _err
    raise IOError("Thorlabs Kinesis Error [{}] {}: {} ".format(retval, err_name, description))
OSError: Thorlabs Kinesis Error [3] FT_DeviceNotOpened: The Device must be opened before it can be accessed. See the appropriate Open function for your device. 

2018-03-06T13:19:58|CRITICAL|root|Unhandled exception:Traceback (most recent call last):
  File "C:\Users\lab\Documents\foundry_scope\ScopeFoundry\hardware.py", line 196, in enable_connection
    self.connect()
  File "C:\Users\lab\Documents\foundry_scope\ScopeFoundryHW\thorlabs_stepper_motors\thorlabs_stepper_controller_hw.py", line 72, in connect
    debug=S['debug_mode'])
  File "C:\Users\lab\Documents\foundry_scope\ScopeFoundryHW\thorlabs_stepper_motors\thorlabs_stepper_controller_dev.py", line 121, in __init__
    _err(S.SBC_Open(self._id))
  File "C:\Users\lab\Documents\foundry_scope\ScopeFoundryHW\thorlabs_stepper_motors\thorlabs_stepper_controller_dev.py", line 65, in _err
    raise IOError("Thorlabs Kinesis Error [{}] {}: {} ".format(retval, err_name, description))
OSError: Thorlabs Kinesis Error [3] FT_DeviceNotOpened: The Device must be opened before it can be accessed. See the appropriate Open function for your device. 

2018-03-06T13:24:30|CRITICAL|root|Unhandled exception:Traceback (most recent call last):
  File "C:\Users\lab\Documents\foundry_scope\ScopeFoundry\hardware.py", line 196, in enable_connection
    self.connect()
  File "C:\Users\lab\Documents\foundry_scope\ScopeFoundryHW\thorlabs_stepper_motors\thorlabs_stepper_controller_hw.py", line 72, in connect
    debug=S['debug_mode'])
  File "C:\Users\lab\Documents\foundry_scope\ScopeFoundryHW\thorlabs_stepper_motors\thorlabs_stepper_controller_dev.py", line 121, in __init__
    _err(S.SBC_Open(self._id))
  File "C:\Users\lab\Documents\foundry_scope\ScopeFoundryHW\thorlabs_stepper_motors\thorlabs_stepper_controller_dev.py", line 65, in _err
    raise IOError("Thorlabs Kinesis Error [{}] {}: {} ".format(retval, err_name, description))
OSError: Thorlabs Kinesis Error [3] FT_DeviceNotOpened: The Device must be opened before it can be accessed. See the appropriate Open function for your device. 

