2019-06-17T18:45:18|CRITICAL|root|Unhandled exception:Traceback (most recent call last):
  File "C:\Users\lab\Documents\foundry_scope\ScopeFoundry\hardware.py", line 215, in enable_connection
    raise err
  File "C:\Users\lab\Documents\foundry_scope\ScopeFoundry\hardware.py", line 205, in enable_connection
    self.connect()
  File "C:\Users\lab\Documents\foundry_scope\ScopeFoundryHW\picoquant\hydraharp_hw.py", line 61, in connect
    debug=S['debug_mode'])
  File "C:\Users\lab\Documents\foundry_scope\ScopeFoundryHW\picoquant\hydraharp_dev.py", line 100, in __init__
    raise err
  File "C:\Users\lab\Documents\foundry_scope\ScopeFoundryHW\picoquant\hydraharp_dev.py", line 39, in __init__
    self._err(self.hhlib.HH_OpenDevice(self.devnum, hw_serial))
  File "C:\Users\lab\Documents\foundry_scope\ScopeFoundryHW\picoquant\hydraharp_dev.py", line 111, in _err
    raise IOError("HydraHarp Error {}: {}".format(retcode, self.err_message))
OSError: HydraHarp Error -2: HH_ERROR_DEVICE_BUSY

