2021-11-15T17:13:06|CRITICAL|root|Unhandled exception:Traceback (most recent call last):
  File "C:\Users\RAMAN\workspace\NearField\ScopeFoundry\hardware.py", line 220, in enable_connection
    raise err
  File "C:\Users\RAMAN\workspace\NearField\ScopeFoundry\hardware.py", line 210, in enable_connection
    self.connect()
  File "C:\Users\RAMAN\workspace\NearField\ScopeFoundryHW\thorlabs_powermeter\thorlabs_powermeter.py", line 53, in connect
    self.power_meter = ThorlabsPM100D(debug=self.settings['debug_mode'], port=self.settings['port'])
  File "C:\Users\RAMAN\workspace\NearField\ScopeFoundryHW\thorlabs_powermeter\thorlabs_pm100d.py", line 35, in __init__
    self.pm = self.visa_resource_manager.get_instrument(port)
  File "C:\Users\RAMAN\.conda\envs\scopefoundry\lib\site-packages\pyvisa\highlevel.py", line 3358, in get_instrument
    resource_name, access_mode, open_timeout, resource_pyclass, **kwargs
  File "C:\Users\RAMAN\.conda\envs\scopefoundry\lib\site-packages\pyvisa\highlevel.py", line 3304, in open_resource
    res.open(access_mode, open_timeout)
  File "C:\Users\RAMAN\.conda\envs\scopefoundry\lib\site-packages\pyvisa\resources\resource.py", line 298, in open
    self._resource_name, access_mode, open_timeout
  File "C:\Users\RAMAN\.conda\envs\scopefoundry\lib\site-packages\pyvisa\highlevel.py", line 3232, in open_bare_resource
    return self.visalib.open(self.session, resource_name, access_mode, open_timeout)
  File "C:\Users\RAMAN\.conda\envs\scopefoundry\lib\site-packages\pyvisa\ctwrapper\functions.py", line 1852, in open
    session, resource_name, access_mode, open_timeout, byref(out_session)
  File "C:\Users\RAMAN\.conda\envs\scopefoundry\lib\site-packages\pyvisa\ctwrapper\highlevel.py", line 222, in _return_handler
    return self.handle_return_value(session, ret_value)  # type: ignore
  File "C:\Users\RAMAN\.conda\envs\scopefoundry\lib\site-packages\pyvisa\highlevel.py", line 251, in handle_return_value
    raise errors.VisaIOError(rv)
pyvisa.errors.VisaIOError: VI_ERROR_RSRC_NFOUND (-1073807343): Insufficient location information or the requested device or resource is not present in the system.

2021-11-15T17:13:11|CRITICAL|root|Unhandled exception:Traceback (most recent call last):
  File "C:\Users\RAMAN\workspace\NearField\ScopeFoundry\hardware.py", line 220, in enable_connection
    raise err
  File "C:\Users\RAMAN\workspace\NearField\ScopeFoundry\hardware.py", line 210, in enable_connection
    self.connect()
  File "C:\Users\RAMAN\workspace\NearField\ScopeFoundryHW\pololu_servo\multi_servo_hw.py", line 56, in connect
    raw.read_from_hardware()
  File "C:\Users\RAMAN\workspace\NearField\ScopeFoundry\logged_quantity.py", line 195, in read_from_hardware
    val = self.hardware_read_func()
  File "C:\Users\RAMAN\workspace\NearField\ScopeFoundryHW\pololu_servo\multi_servo_hw.py", line 52, in <lambda>
    read_func=lambda n=servo_num: self.dev.read_position(n),
  File "C:\Users\RAMAN\workspace\NearField\ScopeFoundryHW\pololu_servo\pololu_interface.py", line 84, in read_position
    lsb = resp[0]
IndexError: index out of range

