2021-11-15T18:22:48|CRITICAL|root|Unhandled exception:Traceback (most recent call last):
  File "C:\Users\RAMAN\.p2\pool\plugins\org.python.pydev.core_7.5.0.202001101138\pysrc\pydevd.py", line 3129, in <module>
    main()
  File "C:\Users\RAMAN\.p2\pool\plugins\org.python.pydev.core_7.5.0.202001101138\pysrc\pydevd.py", line 3122, in main
    globals = debugger.run(setup['file'], None, None, is_module)
  File "C:\Users\RAMAN\.p2\pool\plugins\org.python.pydev.core_7.5.0.202001101138\pysrc\pydevd.py", line 2195, in run
    return self._exec(is_module, entry_point_fn, module_name, file, globals, locals)
  File "C:\Users\RAMAN\.p2\pool\plugins\org.python.pydev.core_7.5.0.202001101138\pysrc\pydevd.py", line 2202, in _exec
    pydev_imports.execfile(file, globals, locals)  # execute the script
  File "C:\Users\RAMAN\.p2\pool\plugins\org.python.pydev.core_7.5.0.202001101138\pysrc\_pydev_imps\_pydev_execfile.py", line 25, in execfile
    exec(compile(contents+"\n", file, 'exec'), glob, loc)
  File "C:\Users\RAMAN\workspace\NearField\NearFieldMicroscope\near_field_microscope_app.py", line 214, in <module>
    app = NearFieldMicroscope(sys.argv)
  File "C:\Users\RAMAN\workspace\NearField\ScopeFoundry\base_app.py", line 338, in __init__
    self.setup()
  File "C:\Users\RAMAN\workspace\NearField\NearFieldMicroscope\near_field_microscope_app.py", line 202, in setup
    from ScopeFoundryHW.ni_daq.hw.ni_freq_counter_callback import NI_FreqCounterCallBackHW
  File "C:\Users\RAMAN\workspace\NearField\ScopeFoundryHW\ni_daq\__init__.py", line 4, in <module>
    from ScopeFoundryHW.ni_daq.hw.ni_adc_hw import NI_ADC_HW
  File "C:\Users\RAMAN\workspace\NearField\ScopeFoundryHW\ni_daq\hw\ni_adc_hw.py", line 2, in <module>
    from ScopeFoundryHW.ni_daq.devices.NI_Daq import NI_AdcTask
  File "C:\Users\RAMAN\workspace\NearField\ScopeFoundryHW\ni_daq\devices\__init__.py", line 1, in <module>
    from .ni_task_wrap import NamedTask, NI_TaskWrap
  File "C:\Users\RAMAN\workspace\NearField\ScopeFoundryHW\ni_daq\devices\ni_task_wrap.py", line 1, in <module>
    import PyDAQmx as mx
  File "C:\Users\RAMAN\.conda\envs\scopefoundry\lib\site-packages\PyDAQmx\__init__.py", line 3, in <module>
    from DAQmxTypes import *
ModuleNotFoundError: No module named 'DAQmxTypes'

