2021-12-23T13:03:24|INFO|HydraHarpOptimizerMeasure|hydraharp_channel_optimizer start_stop False
2021-12-23T13:03:24|INFO|HydraHarpOptimizerMeasure|measurement hydraharp_channel_optimizer stopping stop_first
2021-12-23T13:03:24|INFO|HydraHarpHistogramMeasure|hydraharp_histogram start_stop False
2021-12-23T13:03:24|INFO|HydraHarpHistogramMeasure|measurement hydraharp_histogram stopping stop_first
2021-12-23T13:03:24|INFO|PowerScanMeasure|power_scan start_stop False
2021-12-23T13:03:24|INFO|PowerScanMeasure|measurement power_scan stopping stop_first
2021-12-23T13:03:24|INFO|PowerMeterOptimizerMeasure|powermeter_optimizer start_stop False
2021-12-23T13:03:24|INFO|PowerMeterOptimizerMeasure|measurement powermeter_optimizer stopping stop_first
2021-12-23T13:03:24|INFO|Sequencer|sequencer start_stop False
2021-12-23T13:03:24|INFO|Sequencer|measurement sequencer stopping stop_first
2021-12-23T13:03:24|INFO|APDOptimizerCBMeasurement|apd_optimizer start_stop False
2021-12-23T13:03:24|INFO|APDOptimizerCBMeasurement|measurement apd_optimizer stopping stop_first
2021-12-23T13:03:24|INFO|NearFieldMicroscope|setting up figures for hydraharp_channel_optimizer measurement hydraharp_channel_optimizer
2021-12-23T13:03:24|INFO|HydraHarpOptimizerMeasure|hydraharp_channel_optimizer start_stop False
2021-12-23T13:03:24|INFO|HydraHarpOptimizerMeasure|measurement hydraharp_channel_optimizer stopping stop_first
2021-12-23T13:03:24|INFO|NearFieldMicroscope|setting up figures for hydraharp_histogram measurement hydraharp_histogram
2021-12-23T13:03:24|INFO|NearFieldMicroscope|setting up figures for power_scan measurement power_scan
2021-12-23T13:03:24|INFO|PowerScanMeasure|power_scan start_stop False
2021-12-23T13:03:24|INFO|PowerScanMeasure|measurement power_scan stopping stop_first
2021-12-23T13:03:25|INFO|NearFieldMicroscope|setting up figures for powermeter_optimizer measurement powermeter_optimizer
2021-12-23T13:03:25|INFO|PowerMeterOptimizerMeasure|powermeter_optimizer start_stop False
2021-12-23T13:03:25|INFO|PowerMeterOptimizerMeasure|measurement powermeter_optimizer stopping stop_first
2021-12-23T13:03:25|INFO|NearFieldMicroscope|setting up figures for sequencer measurement sequencer
2021-12-23T13:03:25|INFO|Sequencer|sequencer start_stop False
2021-12-23T13:03:25|INFO|Sequencer|measurement sequencer stopping stop_first
2021-12-23T13:03:25|WARNING|HydraHarpOptimizerMeasure|Measurement.gui is deprecated, use Measurement.app <class 'DeprecationWarning'>
2021-12-23T13:03:25|WARNING|HydraHarpHistogramMeasure|Measurement.gui is deprecated, use Measurement.app <class 'DeprecationWarning'>
2021-12-23T13:03:25|WARNING|PowerScanMeasure|Measurement.gui is deprecated, use Measurement.app <class 'DeprecationWarning'>
2021-12-23T13:03:25|WARNING|PowerMeterOptimizerMeasure|Measurement.gui is deprecated, use Measurement.app <class 'DeprecationWarning'>
2021-12-23T13:03:25|WARNING|Sequencer|Measurement.gui is deprecated, use Measurement.app <class 'DeprecationWarning'>
2021-12-23T13:03:25|WARNING|APDOptimizerCBMeasurement|Measurement.gui is deprecated, use Measurement.app <class 'DeprecationWarning'>
2021-12-23T13:03:25|INFO|NearFieldMicroscope|setting up figures for apd_optimizer measurement apd_optimizer
2021-12-23T13:03:25|INFO|APDOptimizerCBMeasurement|apd_optimizer start_stop False
2021-12-23T13:03:25|INFO|APDOptimizerCBMeasurement|measurement apd_optimizer stopping stop_first
2021-12-23T13:03:25|INFO|NearFieldMicroscope|ini settings loading from near_field_microscope_defaults.ini
2021-12-23T13:03:25|DEBUG|FileLQ|save_dir: update_value 'C:\\Users\\RAMAN\\workspace\\NearField\\NearFieldMicroscope\\data' --> 'E:\\Natalie'    sender=None
2021-12-23T13:03:25|DEBUG|FileLQ|save_dir: different values C:\Users\RAMAN\workspace\NearField\NearFieldMicroscope\data E:\Natalie
2021-12-23T13:03:25|INFO|NearFieldMicroscope|hardware/hydraharp
2021-12-23T13:03:25|INFO|NearFieldMicroscope|hardware/pololu_maestro
2021-12-23T13:03:29|INFO|NearFieldMicroscope|hardware/power_wheel
2021-12-23T13:03:29|INFO|NearFieldMicroscope|hardware/thorlabs_powermeter
2021-12-23T13:03:29|INFO|NearFieldMicroscope|hardware/motorized_polarizer
2021-12-23T13:03:29|INFO|NearFieldMicroscope|hardware/apd_counter
2021-12-23T13:03:29|INFO|NearFieldMicroscope|ini settings loaded from: near_field_microscope_defaults.ini
2021-12-23T13:03:41|DEBUG|ScopeFoundryHW.thorlabs_powermeter.thorlabs_pm100d|get_auto_range '1\n'
2021-12-23T13:03:41|DEBUG|ScopeFoundryHW.thorlabs_powermeter.thorlabs_pm100d|get_auto_range '1\n'
2021-12-23T13:07:22|CRITICAL|root|Unhandled exception:Traceback (most recent call last):
  File "C:\Users\RAMAN\workspace\NearField\ScopeFoundry\logged_quantity.py", line 842, in update_math
    new_val = self.math_func(*lq_vals)
  File "C:\Users\RAMAN\workspace\NearField\ScopeFoundryHW\pololu_servo\multi_servo_hw.py", line 36, in <lambda>
    func=lambda raw, rmin, rmax, scale: scale*( (raw - rmin)/(rmax-rmin) ),
ZeroDivisionError: float division by zero

2021-12-23T13:07:33|INFO|PowerMeterOptimizerMeasure|powermeter_optimizer start_stop True
2021-12-23T13:07:33|INFO|PowerMeterOptimizerMeasure|measurement powermeter_optimizer start called from thread: 9840
2021-12-23T15:34:29|INFO|PowerScanMeasure|power_scan start_stop True
2021-12-23T15:34:29|INFO|PowerScanMeasure|measurement power_scan start called from thread: 9840
2021-12-23T15:34:35|WARNING|LoggedQuantity|count_rate read_from_hardware called when not connected to hardware
2021-12-23T15:34:41|WARNING|LoggedQuantity|count_rate read_from_hardware called when not connected to hardware
2021-12-23T15:34:47|WARNING|LoggedQuantity|count_rate read_from_hardware called when not connected to hardware
2021-12-23T15:34:54|WARNING|LoggedQuantity|count_rate read_from_hardware called when not connected to hardware
2021-12-23T15:35:01|WARNING|LoggedQuantity|count_rate read_from_hardware called when not connected to hardware
2021-12-23T15:35:08|WARNING|LoggedQuantity|count_rate read_from_hardware called when not connected to hardware
2021-12-23T15:35:15|WARNING|LoggedQuantity|count_rate read_from_hardware called when not connected to hardware
2021-12-23T15:35:23|WARNING|LoggedQuantity|count_rate read_from_hardware called when not connected to hardware
2021-12-23T15:35:29|WARNING|LoggedQuantity|count_rate read_from_hardware called when not connected to hardware
2021-12-23T15:35:35|WARNING|LoggedQuantity|count_rate read_from_hardware called when not connected to hardware
2021-12-23T15:35:41|WARNING|LoggedQuantity|count_rate read_from_hardware called when not connected to hardware
2021-12-23T15:35:48|WARNING|LoggedQuantity|count_rate read_from_hardware called when not connected to hardware
2021-12-23T15:35:48|INFO|APDOptimizerCBMeasurement|apd_optimizer start_stop True
2021-12-23T15:35:48|INFO|APDOptimizerCBMeasurement|measurement apd_optimizer start called from thread: 9840
2021-12-23T15:35:48|DEBUG|ScopeFoundryHW.ni_daq.devices.ni_counter_task|NI_CounterTask.set_channel-- Dev1/ctr0 /Dev1/PFI0
2021-12-23T15:36:03|CRITICAL|root|Unhandled exception:Traceback (most recent call last):
  File "C:\Users\RAMAN\workspace\NearField\ScopeFoundryHW\ni_daq\devices\ni_counter_task.py", line 152, in read_buffer
    self.task.ReadCounterF64(-1, timeout, data, count, mx.byref(read_count), None)
  File "<string>", line 3, in ReadCounterF64
  File "<string>", line 2, in function
  File "C:\ProgramData\Anaconda3\lib\site-packages\PyDAQmx\DAQmxFunctions.py", line 62, in mafunction
    raise exception_class(errBuff.value.decode("utf-8"), f.__name__)
PyDAQmx.DAQmxFunctions.SamplesNoLongerAvailableError: The application is not able to keep up with the hardware acquisition.

Increasing the buffer size, reading the data more frequently, or specifying a fixed number of samples to read instead of reading all available samples might correct the problem.
Property: DAQmx_Read_RelativeTo
Corresponding Value: DAQmx_Val_CurrReadPos
Property: DAQmx_Read_Offset
Corresponding Value: 0

Task Name: _unnamedTask<0>

Status Code: -200279
 in function DAQmxReadCounterF64

During handling of the above exception, another exception occurred:

Traceback (most recent call last):
  File "_ctypes/callbacks.c", line 232, in 'calling callback function'
  File "C:\ProgramData\Anaconda3\lib\site-packages\PyDAQmx\Task.py", line 46, in EveryNCallback_py
    getattr(self,name)()
  File "C:\Users\RAMAN\workspace\NearField\ScopeFoundryHW\ni_daq\hw\ni_freq_counter_callback.py", line 87, in counter_callback
    raise err
  File "C:\Users\RAMAN\workspace\NearField\ScopeFoundryHW\ni_daq\hw\ni_freq_counter_callback.py", line 83, in counter_callback
    self.current_count = self.counter_task.read_buffer(count=self.n_samples_cb)[-1]
  File "C:\Users\RAMAN\workspace\NearField\ScopeFoundryHW\ni_daq\devices\ni_counter_task.py", line 154, in read_buffer
    self.error(err)
  File "C:\Users\RAMAN\workspace\NearField\ScopeFoundryHW\ni_daq\devices\ni_task_wrap.py", line 42, in error
    logger.error('Error calling "{}": {}'.format( err.fname, err.mess ))
AttributeError: 'SamplesNoLongerAvailableError' object has no attribute 'mess'

2021-12-23T15:36:05|CRITICAL|root|Unhandled exception:Traceback (most recent call last):
  File "C:\Users\RAMAN\workspace\NearField\ScopeFoundryHW\ni_daq\devices\ni_counter_task.py", line 152, in read_buffer
    self.task.ReadCounterF64(-1, timeout, data, count, mx.byref(read_count), None)
  File "<string>", line 3, in ReadCounterF64
  File "<string>", line 2, in function
  File "C:\ProgramData\Anaconda3\lib\site-packages\PyDAQmx\DAQmxFunctions.py", line 62, in mafunction
    raise exception_class(errBuff.value.decode("utf-8"), f.__name__)
PyDAQmx.DAQmxFunctions.SamplesNoLongerAvailableError: The application is not able to keep up with the hardware acquisition.

Increasing the buffer size, reading the data more frequently, or specifying a fixed number of samples to read instead of reading all available samples might correct the problem.
Property: DAQmx_Read_RelativeTo
Corresponding Value: DAQmx_Val_CurrReadPos
Property: DAQmx_Read_Offset
Corresponding Value: 0

Task Name: _unnamedTask<0>

Status Code: -200279
 in function DAQmxReadCounterF64

During handling of the above exception, another exception occurred:

Traceback (most recent call last):
  File "_ctypes/callbacks.c", line 232, in 'calling callback function'
  File "C:\ProgramData\Anaconda3\lib\site-packages\PyDAQmx\Task.py", line 46, in EveryNCallback_py
    getattr(self,name)()
  File "C:\Users\RAMAN\workspace\NearField\ScopeFoundryHW\ni_daq\hw\ni_freq_counter_callback.py", line 87, in counter_callback
    raise err
  File "C:\Users\RAMAN\workspace\NearField\ScopeFoundryHW\ni_daq\hw\ni_freq_counter_callback.py", line 83, in counter_callback
    self.current_count = self.counter_task.read_buffer(count=self.n_samples_cb)[-1]
  File "C:\Users\RAMAN\workspace\NearField\ScopeFoundryHW\ni_daq\devices\ni_counter_task.py", line 154, in read_buffer
    self.error(err)
  File "C:\Users\RAMAN\workspace\NearField\ScopeFoundryHW\ni_daq\devices\ni_task_wrap.py", line 42, in error
    logger.error('Error calling "{}": {}'.format( err.fname, err.mess ))
AttributeError: 'SamplesNoLongerAvailableError' object has no attribute 'mess'

2021-12-23T15:36:09|CRITICAL|root|Unhandled exception:Traceback (most recent call last):
  File "C:\Users\RAMAN\workspace\NearField\ScopeFoundryHW\ni_daq\devices\ni_counter_task.py", line 152, in read_buffer
    self.task.ReadCounterF64(-1, timeout, data, count, mx.byref(read_count), None)
  File "<string>", line 3, in ReadCounterF64
  File "<string>", line 2, in function
  File "C:\ProgramData\Anaconda3\lib\site-packages\PyDAQmx\DAQmxFunctions.py", line 62, in mafunction
    raise exception_class(errBuff.value.decode("utf-8"), f.__name__)
PyDAQmx.DAQmxFunctions.SamplesNoLongerAvailableError: The application is not able to keep up with the hardware acquisition.

Increasing the buffer size, reading the data more frequently, or specifying a fixed number of samples to read instead of reading all available samples might correct the problem.
Property: DAQmx_Read_RelativeTo
Corresponding Value: DAQmx_Val_CurrReadPos
Property: DAQmx_Read_Offset
Corresponding Value: 0

Task Name: _unnamedTask<0>

Status Code: -200279
 in function DAQmxReadCounterF64

During handling of the above exception, another exception occurred:

Traceback (most recent call last):
  File "_ctypes/callbacks.c", line 232, in 'calling callback function'
  File "C:\ProgramData\Anaconda3\lib\site-packages\PyDAQmx\Task.py", line 46, in EveryNCallback_py
    getattr(self,name)()
  File "C:\Users\RAMAN\workspace\NearField\ScopeFoundryHW\ni_daq\hw\ni_freq_counter_callback.py", line 87, in counter_callback
    raise err
  File "C:\Users\RAMAN\workspace\NearField\ScopeFoundryHW\ni_daq\hw\ni_freq_counter_callback.py", line 83, in counter_callback
    self.current_count = self.counter_task.read_buffer(count=self.n_samples_cb)[-1]
  File "C:\Users\RAMAN\workspace\NearField\ScopeFoundryHW\ni_daq\devices\ni_counter_task.py", line 154, in read_buffer
    self.error(err)
  File "C:\Users\RAMAN\workspace\NearField\ScopeFoundryHW\ni_daq\devices\ni_task_wrap.py", line 42, in error
    logger.error('Error calling "{}": {}'.format( err.fname, err.mess ))
AttributeError: 'SamplesNoLongerAvailableError' object has no attribute 'mess'

2021-12-23T15:36:12|CRITICAL|root|Unhandled exception:Traceback (most recent call last):
  File "C:\Users\RAMAN\workspace\NearField\ScopeFoundryHW\ni_daq\devices\ni_counter_task.py", line 152, in read_buffer
    self.task.ReadCounterF64(-1, timeout, data, count, mx.byref(read_count), None)
  File "<string>", line 3, in ReadCounterF64
  File "<string>", line 2, in function
  File "C:\ProgramData\Anaconda3\lib\site-packages\PyDAQmx\DAQmxFunctions.py", line 62, in mafunction
    raise exception_class(errBuff.value.decode("utf-8"), f.__name__)
PyDAQmx.DAQmxFunctions.SamplesNoLongerAvailableError: The application is not able to keep up with the hardware acquisition.

Increasing the buffer size, reading the data more frequently, or specifying a fixed number of samples to read instead of reading all available samples might correct the problem.
Property: DAQmx_Read_RelativeTo
Corresponding Value: DAQmx_Val_CurrReadPos
Property: DAQmx_Read_Offset
Corresponding Value: 0

Task Name: _unnamedTask<0>

Status Code: -200279
 in function DAQmxReadCounterF64

During handling of the above exception, another exception occurred:

Traceback (most recent call last):
  File "_ctypes/callbacks.c", line 232, in 'calling callback function'
  File "C:\ProgramData\Anaconda3\lib\site-packages\PyDAQmx\Task.py", line 46, in EveryNCallback_py
    getattr(self,name)()
  File "C:\Users\RAMAN\workspace\NearField\ScopeFoundryHW\ni_daq\hw\ni_freq_counter_callback.py", line 87, in counter_callback
    raise err
  File "C:\Users\RAMAN\workspace\NearField\ScopeFoundryHW\ni_daq\hw\ni_freq_counter_callback.py", line 83, in counter_callback
    self.current_count = self.counter_task.read_buffer(count=self.n_samples_cb)[-1]
  File "C:\Users\RAMAN\workspace\NearField\ScopeFoundryHW\ni_daq\devices\ni_counter_task.py", line 154, in read_buffer
    self.error(err)
  File "C:\Users\RAMAN\workspace\NearField\ScopeFoundryHW\ni_daq\devices\ni_task_wrap.py", line 42, in error
    logger.error('Error calling "{}": {}'.format( err.fname, err.mess ))
AttributeError: 'SamplesNoLongerAvailableError' object has no attribute 'mess'

2021-12-23T15:36:14|CRITICAL|root|Unhandled exception:Traceback (most recent call last):
  File "C:\Users\RAMAN\workspace\NearField\ScopeFoundryHW\ni_daq\devices\ni_counter_task.py", line 152, in read_buffer
    self.task.ReadCounterF64(-1, timeout, data, count, mx.byref(read_count), None)
  File "<string>", line 3, in ReadCounterF64
  File "<string>", line 2, in function
  File "C:\ProgramData\Anaconda3\lib\site-packages\PyDAQmx\DAQmxFunctions.py", line 62, in mafunction
    raise exception_class(errBuff.value.decode("utf-8"), f.__name__)
PyDAQmx.DAQmxFunctions.SamplesNoLongerAvailableError: The application is not able to keep up with the hardware acquisition.

Increasing the buffer size, reading the data more frequently, or specifying a fixed number of samples to read instead of reading all available samples might correct the problem.
Property: DAQmx_Read_RelativeTo
Corresponding Value: DAQmx_Val_CurrReadPos
Property: DAQmx_Read_Offset
Corresponding Value: 0

Task Name: _unnamedTask<0>

Status Code: -200279
 in function DAQmxReadCounterF64

During handling of the above exception, another exception occurred:

Traceback (most recent call last):
  File "_ctypes/callbacks.c", line 232, in 'calling callback function'
  File "C:\ProgramData\Anaconda3\lib\site-packages\PyDAQmx\Task.py", line 46, in EveryNCallback_py
    getattr(self,name)()
  File "C:\Users\RAMAN\workspace\NearField\ScopeFoundryHW\ni_daq\hw\ni_freq_counter_callback.py", line 87, in counter_callback
    raise err
  File "C:\Users\RAMAN\workspace\NearField\ScopeFoundryHW\ni_daq\hw\ni_freq_counter_callback.py", line 83, in counter_callback
    self.current_count = self.counter_task.read_buffer(count=self.n_samples_cb)[-1]
  File "C:\Users\RAMAN\workspace\NearField\ScopeFoundryHW\ni_daq\devices\ni_counter_task.py", line 154, in read_buffer
    self.error(err)
  File "C:\Users\RAMAN\workspace\NearField\ScopeFoundryHW\ni_daq\devices\ni_task_wrap.py", line 42, in error
    logger.error('Error calling "{}": {}'.format( err.fname, err.mess ))
AttributeError: 'SamplesNoLongerAvailableError' object has no attribute 'mess'

2021-12-23T15:36:17|CRITICAL|root|Unhandled exception:Traceback (most recent call last):
  File "C:\Users\RAMAN\workspace\NearField\ScopeFoundryHW\ni_daq\devices\ni_counter_task.py", line 152, in read_buffer
    self.task.ReadCounterF64(-1, timeout, data, count, mx.byref(read_count), None)
  File "<string>", line 3, in ReadCounterF64
  File "<string>", line 2, in function
  File "C:\ProgramData\Anaconda3\lib\site-packages\PyDAQmx\DAQmxFunctions.py", line 62, in mafunction
    raise exception_class(errBuff.value.decode("utf-8"), f.__name__)
PyDAQmx.DAQmxFunctions.SamplesNoLongerAvailableError: The application is not able to keep up with the hardware acquisition.

Increasing the buffer size, reading the data more frequently, or specifying a fixed number of samples to read instead of reading all available samples might correct the problem.
Property: DAQmx_Read_RelativeTo
Corresponding Value: DAQmx_Val_CurrReadPos
Property: DAQmx_Read_Offset
Corresponding Value: 0

Task Name: _unnamedTask<0>

Status Code: -200279
 in function DAQmxReadCounterF64

During handling of the above exception, another exception occurred:

Traceback (most recent call last):
  File "_ctypes/callbacks.c", line 232, in 'calling callback function'
  File "C:\ProgramData\Anaconda3\lib\site-packages\PyDAQmx\Task.py", line 46, in EveryNCallback_py
    getattr(self,name)()
  File "C:\Users\RAMAN\workspace\NearField\ScopeFoundryHW\ni_daq\hw\ni_freq_counter_callback.py", line 87, in counter_callback
    raise err
  File "C:\Users\RAMAN\workspace\NearField\ScopeFoundryHW\ni_daq\hw\ni_freq_counter_callback.py", line 83, in counter_callback
    self.current_count = self.counter_task.read_buffer(count=self.n_samples_cb)[-1]
  File "C:\Users\RAMAN\workspace\NearField\ScopeFoundryHW\ni_daq\devices\ni_counter_task.py", line 154, in read_buffer
    self.error(err)
  File "C:\Users\RAMAN\workspace\NearField\ScopeFoundryHW\ni_daq\devices\ni_task_wrap.py", line 42, in error
    logger.error('Error calling "{}": {}'.format( err.fname, err.mess ))
AttributeError: 'SamplesNoLongerAvailableError' object has no attribute 'mess'

2021-12-23T15:36:22|CRITICAL|root|Unhandled exception:Traceback (most recent call last):
  File "C:\Users\RAMAN\workspace\NearField\ScopeFoundryHW\ni_daq\devices\ni_counter_task.py", line 152, in read_buffer
    self.task.ReadCounterF64(-1, timeout, data, count, mx.byref(read_count), None)
  File "<string>", line 3, in ReadCounterF64
  File "<string>", line 2, in function
  File "C:\ProgramData\Anaconda3\lib\site-packages\PyDAQmx\DAQmxFunctions.py", line 62, in mafunction
    raise exception_class(errBuff.value.decode("utf-8"), f.__name__)
PyDAQmx.DAQmxFunctions.SamplesNoLongerAvailableError: The application is not able to keep up with the hardware acquisition.

Increasing the buffer size, reading the data more frequently, or specifying a fixed number of samples to read instead of reading all available samples might correct the problem.
Property: DAQmx_Read_RelativeTo
Corresponding Value: DAQmx_Val_CurrReadPos
Property: DAQmx_Read_Offset
Corresponding Value: 0

Task Name: _unnamedTask<0>

Status Code: -200279
 in function DAQmxReadCounterF64

During handling of the above exception, another exception occurred:

Traceback (most recent call last):
  File "_ctypes/callbacks.c", line 232, in 'calling callback function'
  File "C:\ProgramData\Anaconda3\lib\site-packages\PyDAQmx\Task.py", line 46, in EveryNCallback_py
    getattr(self,name)()
  File "C:\Users\RAMAN\workspace\NearField\ScopeFoundryHW\ni_daq\hw\ni_freq_counter_callback.py", line 87, in counter_callback
    raise err
  File "C:\Users\RAMAN\workspace\NearField\ScopeFoundryHW\ni_daq\hw\ni_freq_counter_callback.py", line 83, in counter_callback
    self.current_count = self.counter_task.read_buffer(count=self.n_samples_cb)[-1]
  File "C:\Users\RAMAN\workspace\NearField\ScopeFoundryHW\ni_daq\devices\ni_counter_task.py", line 154, in read_buffer
    self.error(err)
  File "C:\Users\RAMAN\workspace\NearField\ScopeFoundryHW\ni_daq\devices\ni_task_wrap.py", line 42, in error
    logger.error('Error calling "{}": {}'.format( err.fname, err.mess ))
AttributeError: 'SamplesNoLongerAvailableError' object has no attribute 'mess'

2021-12-23T15:36:26|CRITICAL|root|Unhandled exception:Traceback (most recent call last):
  File "C:\Users\RAMAN\workspace\NearField\ScopeFoundryHW\ni_daq\devices\ni_counter_task.py", line 152, in read_buffer
    self.task.ReadCounterF64(-1, timeout, data, count, mx.byref(read_count), None)
  File "<string>", line 3, in ReadCounterF64
  File "<string>", line 2, in function
  File "C:\ProgramData\Anaconda3\lib\site-packages\PyDAQmx\DAQmxFunctions.py", line 62, in mafunction
    raise exception_class(errBuff.value.decode("utf-8"), f.__name__)
PyDAQmx.DAQmxFunctions.SamplesNoLongerAvailableError: The application is not able to keep up with the hardware acquisition.

Increasing the buffer size, reading the data more frequently, or specifying a fixed number of samples to read instead of reading all available samples might correct the problem.
Property: DAQmx_Read_RelativeTo
Corresponding Value: DAQmx_Val_CurrReadPos
Property: DAQmx_Read_Offset
Corresponding Value: 0

Task Name: _unnamedTask<0>

Status Code: -200279
 in function DAQmxReadCounterF64

During handling of the above exception, another exception occurred:

Traceback (most recent call last):
  File "_ctypes/callbacks.c", line 232, in 'calling callback function'
  File "C:\ProgramData\Anaconda3\lib\site-packages\PyDAQmx\Task.py", line 46, in EveryNCallback_py
    getattr(self,name)()
  File "C:\Users\RAMAN\workspace\NearField\ScopeFoundryHW\ni_daq\hw\ni_freq_counter_callback.py", line 87, in counter_callback
    raise err
  File "C:\Users\RAMAN\workspace\NearField\ScopeFoundryHW\ni_daq\hw\ni_freq_counter_callback.py", line 83, in counter_callback
    self.current_count = self.counter_task.read_buffer(count=self.n_samples_cb)[-1]
  File "C:\Users\RAMAN\workspace\NearField\ScopeFoundryHW\ni_daq\devices\ni_counter_task.py", line 154, in read_buffer
    self.error(err)
  File "C:\Users\RAMAN\workspace\NearField\ScopeFoundryHW\ni_daq\devices\ni_task_wrap.py", line 42, in error
    logger.error('Error calling "{}": {}'.format( err.fname, err.mess ))
AttributeError: 'SamplesNoLongerAvailableError' object has no attribute 'mess'

2021-12-23T15:36:27|CRITICAL|root|Unhandled exception:Traceback (most recent call last):
  File "C:\Users\RAMAN\workspace\NearField\ScopeFoundryHW\ni_daq\devices\ni_counter_task.py", line 152, in read_buffer
    self.task.ReadCounterF64(-1, timeout, data, count, mx.byref(read_count), None)
  File "<string>", line 3, in ReadCounterF64
  File "<string>", line 2, in function
  File "C:\ProgramData\Anaconda3\lib\site-packages\PyDAQmx\DAQmxFunctions.py", line 62, in mafunction
    raise exception_class(errBuff.value.decode("utf-8"), f.__name__)
PyDAQmx.DAQmxFunctions.SamplesNoLongerAvailableError: The application is not able to keep up with the hardware acquisition.

Increasing the buffer size, reading the data more frequently, or specifying a fixed number of samples to read instead of reading all available samples might correct the problem.
Property: DAQmx_Read_RelativeTo
Corresponding Value: DAQmx_Val_CurrReadPos
Property: DAQmx_Read_Offset
Corresponding Value: 0

Task Name: _unnamedTask<0>

Status Code: -200279
 in function DAQmxReadCounterF64

During handling of the above exception, another exception occurred:

Traceback (most recent call last):
  File "_ctypes/callbacks.c", line 232, in 'calling callback function'
  File "C:\ProgramData\Anaconda3\lib\site-packages\PyDAQmx\Task.py", line 46, in EveryNCallback_py
    getattr(self,name)()
  File "C:\Users\RAMAN\workspace\NearField\ScopeFoundryHW\ni_daq\hw\ni_freq_counter_callback.py", line 87, in counter_callback
    raise err
  File "C:\Users\RAMAN\workspace\NearField\ScopeFoundryHW\ni_daq\hw\ni_freq_counter_callback.py", line 83, in counter_callback
    self.current_count = self.counter_task.read_buffer(count=self.n_samples_cb)[-1]
  File "C:\Users\RAMAN\workspace\NearField\ScopeFoundryHW\ni_daq\devices\ni_counter_task.py", line 154, in read_buffer
    self.error(err)
  File "C:\Users\RAMAN\workspace\NearField\ScopeFoundryHW\ni_daq\devices\ni_task_wrap.py", line 42, in error
    logger.error('Error calling "{}": {}'.format( err.fname, err.mess ))
AttributeError: 'SamplesNoLongerAvailableError' object has no attribute 'mess'

2021-12-23T15:36:30|CRITICAL|root|Unhandled exception:Traceback (most recent call last):
  File "C:\Users\RAMAN\workspace\NearField\ScopeFoundryHW\ni_daq\devices\ni_counter_task.py", line 152, in read_buffer
    self.task.ReadCounterF64(-1, timeout, data, count, mx.byref(read_count), None)
  File "<string>", line 3, in ReadCounterF64
  File "<string>", line 2, in function
  File "C:\ProgramData\Anaconda3\lib\site-packages\PyDAQmx\DAQmxFunctions.py", line 62, in mafunction
    raise exception_class(errBuff.value.decode("utf-8"), f.__name__)
PyDAQmx.DAQmxFunctions.SamplesNoLongerAvailableError: The application is not able to keep up with the hardware acquisition.

Increasing the buffer size, reading the data more frequently, or specifying a fixed number of samples to read instead of reading all available samples might correct the problem.
Property: DAQmx_Read_RelativeTo
Corresponding Value: DAQmx_Val_CurrReadPos
Property: DAQmx_Read_Offset
Corresponding Value: 0

Task Name: _unnamedTask<0>

Status Code: -200279
 in function DAQmxReadCounterF64

During handling of the above exception, another exception occurred:

Traceback (most recent call last):
  File "_ctypes/callbacks.c", line 232, in 'calling callback function'
  File "C:\ProgramData\Anaconda3\lib\site-packages\PyDAQmx\Task.py", line 46, in EveryNCallback_py
    getattr(self,name)()
  File "C:\Users\RAMAN\workspace\NearField\ScopeFoundryHW\ni_daq\hw\ni_freq_counter_callback.py", line 87, in counter_callback
    raise err
  File "C:\Users\RAMAN\workspace\NearField\ScopeFoundryHW\ni_daq\hw\ni_freq_counter_callback.py", line 83, in counter_callback
    self.current_count = self.counter_task.read_buffer(count=self.n_samples_cb)[-1]
  File "C:\Users\RAMAN\workspace\NearField\ScopeFoundryHW\ni_daq\devices\ni_counter_task.py", line 154, in read_buffer
    self.error(err)
  File "C:\Users\RAMAN\workspace\NearField\ScopeFoundryHW\ni_daq\devices\ni_task_wrap.py", line 42, in error
    logger.error('Error calling "{}": {}'.format( err.fname, err.mess ))
AttributeError: 'SamplesNoLongerAvailableError' object has no attribute 'mess'

2021-12-23T15:36:34|CRITICAL|root|Unhandled exception:Traceback (most recent call last):
  File "C:\Users\RAMAN\workspace\NearField\ScopeFoundryHW\ni_daq\devices\ni_counter_task.py", line 152, in read_buffer
    self.task.ReadCounterF64(-1, timeout, data, count, mx.byref(read_count), None)
  File "<string>", line 3, in ReadCounterF64
  File "<string>", line 2, in function
  File "C:\ProgramData\Anaconda3\lib\site-packages\PyDAQmx\DAQmxFunctions.py", line 62, in mafunction
    raise exception_class(errBuff.value.decode("utf-8"), f.__name__)
PyDAQmx.DAQmxFunctions.SamplesNoLongerAvailableError: The application is not able to keep up with the hardware acquisition.

Increasing the buffer size, reading the data more frequently, or specifying a fixed number of samples to read instead of reading all available samples might correct the problem.
Property: DAQmx_Read_RelativeTo
Corresponding Value: DAQmx_Val_CurrReadPos
Property: DAQmx_Read_Offset
Corresponding Value: 0

Task Name: _unnamedTask<0>

Status Code: -200279
 in function DAQmxReadCounterF64

During handling of the above exception, another exception occurred:

Traceback (most recent call last):
  File "_ctypes/callbacks.c", line 232, in 'calling callback function'
  File "C:\ProgramData\Anaconda3\lib\site-packages\PyDAQmx\Task.py", line 46, in EveryNCallback_py
    getattr(self,name)()
  File "C:\Users\RAMAN\workspace\NearField\ScopeFoundryHW\ni_daq\hw\ni_freq_counter_callback.py", line 87, in counter_callback
    raise err
  File "C:\Users\RAMAN\workspace\NearField\ScopeFoundryHW\ni_daq\hw\ni_freq_counter_callback.py", line 83, in counter_callback
    self.current_count = self.counter_task.read_buffer(count=self.n_samples_cb)[-1]
  File "C:\Users\RAMAN\workspace\NearField\ScopeFoundryHW\ni_daq\devices\ni_counter_task.py", line 154, in read_buffer
    self.error(err)
  File "C:\Users\RAMAN\workspace\NearField\ScopeFoundryHW\ni_daq\devices\ni_task_wrap.py", line 42, in error
    logger.error('Error calling "{}": {}'.format( err.fname, err.mess ))
AttributeError: 'SamplesNoLongerAvailableError' object has no attribute 'mess'

2021-12-23T15:36:38|CRITICAL|root|Unhandled exception:Traceback (most recent call last):
  File "C:\Users\RAMAN\workspace\NearField\ScopeFoundryHW\ni_daq\devices\ni_counter_task.py", line 152, in read_buffer
    self.task.ReadCounterF64(-1, timeout, data, count, mx.byref(read_count), None)
  File "<string>", line 3, in ReadCounterF64
  File "<string>", line 2, in function
  File "C:\ProgramData\Anaconda3\lib\site-packages\PyDAQmx\DAQmxFunctions.py", line 62, in mafunction
    raise exception_class(errBuff.value.decode("utf-8"), f.__name__)
PyDAQmx.DAQmxFunctions.SamplesNoLongerAvailableError: The application is not able to keep up with the hardware acquisition.

Increasing the buffer size, reading the data more frequently, or specifying a fixed number of samples to read instead of reading all available samples might correct the problem.
Property: DAQmx_Read_RelativeTo
Corresponding Value: DAQmx_Val_CurrReadPos
Property: DAQmx_Read_Offset
Corresponding Value: 0

Task Name: _unnamedTask<0>

Status Code: -200279
 in function DAQmxReadCounterF64

During handling of the above exception, another exception occurred:

Traceback (most recent call last):
  File "_ctypes/callbacks.c", line 232, in 'calling callback function'
  File "C:\ProgramData\Anaconda3\lib\site-packages\PyDAQmx\Task.py", line 46, in EveryNCallback_py
    getattr(self,name)()
  File "C:\Users\RAMAN\workspace\NearField\ScopeFoundryHW\ni_daq\hw\ni_freq_counter_callback.py", line 87, in counter_callback
    raise err
  File "C:\Users\RAMAN\workspace\NearField\ScopeFoundryHW\ni_daq\hw\ni_freq_counter_callback.py", line 83, in counter_callback
    self.current_count = self.counter_task.read_buffer(count=self.n_samples_cb)[-1]
  File "C:\Users\RAMAN\workspace\NearField\ScopeFoundryHW\ni_daq\devices\ni_counter_task.py", line 154, in read_buffer
    self.error(err)
  File "C:\Users\RAMAN\workspace\NearField\ScopeFoundryHW\ni_daq\devices\ni_task_wrap.py", line 42, in error
    logger.error('Error calling "{}": {}'.format( err.fname, err.mess ))
AttributeError: 'SamplesNoLongerAvailableError' object has no attribute 'mess'

2021-12-23T15:36:43|CRITICAL|root|Unhandled exception:Traceback (most recent call last):
  File "C:\Users\RAMAN\workspace\NearField\ScopeFoundryHW\ni_daq\devices\ni_counter_task.py", line 152, in read_buffer
    self.task.ReadCounterF64(-1, timeout, data, count, mx.byref(read_count), None)
  File "<string>", line 3, in ReadCounterF64
  File "<string>", line 2, in function
  File "C:\ProgramData\Anaconda3\lib\site-packages\PyDAQmx\DAQmxFunctions.py", line 62, in mafunction
    raise exception_class(errBuff.value.decode("utf-8"), f.__name__)
PyDAQmx.DAQmxFunctions.SamplesNoLongerAvailableError: The application is not able to keep up with the hardware acquisition.

Increasing the buffer size, reading the data more frequently, or specifying a fixed number of samples to read instead of reading all available samples might correct the problem.
Property: DAQmx_Read_RelativeTo
Corresponding Value: DAQmx_Val_CurrReadPos
Property: DAQmx_Read_Offset
Corresponding Value: 0

Task Name: _unnamedTask<0>

Status Code: -200279
 in function DAQmxReadCounterF64

During handling of the above exception, another exception occurred:

Traceback (most recent call last):
  File "_ctypes/callbacks.c", line 232, in 'calling callback function'
  File "C:\ProgramData\Anaconda3\lib\site-packages\PyDAQmx\Task.py", line 46, in EveryNCallback_py
    getattr(self,name)()
  File "C:\Users\RAMAN\workspace\NearField\ScopeFoundryHW\ni_daq\hw\ni_freq_counter_callback.py", line 87, in counter_callback
    raise err
  File "C:\Users\RAMAN\workspace\NearField\ScopeFoundryHW\ni_daq\hw\ni_freq_counter_callback.py", line 83, in counter_callback
    self.current_count = self.counter_task.read_buffer(count=self.n_samples_cb)[-1]
  File "C:\Users\RAMAN\workspace\NearField\ScopeFoundryHW\ni_daq\devices\ni_counter_task.py", line 154, in read_buffer
    self.error(err)
  File "C:\Users\RAMAN\workspace\NearField\ScopeFoundryHW\ni_daq\devices\ni_task_wrap.py", line 42, in error
    logger.error('Error calling "{}": {}'.format( err.fname, err.mess ))
AttributeError: 'SamplesNoLongerAvailableError' object has no attribute 'mess'

2021-12-23T15:36:46|CRITICAL|root|Unhandled exception:Traceback (most recent call last):
  File "C:\Users\RAMAN\workspace\NearField\ScopeFoundryHW\ni_daq\devices\ni_counter_task.py", line 152, in read_buffer
    self.task.ReadCounterF64(-1, timeout, data, count, mx.byref(read_count), None)
  File "<string>", line 3, in ReadCounterF64
  File "<string>", line 2, in function
  File "C:\ProgramData\Anaconda3\lib\site-packages\PyDAQmx\DAQmxFunctions.py", line 62, in mafunction
    raise exception_class(errBuff.value.decode("utf-8"), f.__name__)
PyDAQmx.DAQmxFunctions.SamplesNoLongerAvailableError: The application is not able to keep up with the hardware acquisition.

Increasing the buffer size, reading the data more frequently, or specifying a fixed number of samples to read instead of reading all available samples might correct the problem.
Property: DAQmx_Read_RelativeTo
Corresponding Value: DAQmx_Val_CurrReadPos
Property: DAQmx_Read_Offset
Corresponding Value: 0

Task Name: _unnamedTask<0>

Status Code: -200279
 in function DAQmxReadCounterF64

During handling of the above exception, another exception occurred:

Traceback (most recent call last):
  File "_ctypes/callbacks.c", line 232, in 'calling callback function'
  File "C:\ProgramData\Anaconda3\lib\site-packages\PyDAQmx\Task.py", line 46, in EveryNCallback_py
    getattr(self,name)()
  File "C:\Users\RAMAN\workspace\NearField\ScopeFoundryHW\ni_daq\hw\ni_freq_counter_callback.py", line 87, in counter_callback
    raise err
  File "C:\Users\RAMAN\workspace\NearField\ScopeFoundryHW\ni_daq\hw\ni_freq_counter_callback.py", line 83, in counter_callback
    self.current_count = self.counter_task.read_buffer(count=self.n_samples_cb)[-1]
  File "C:\Users\RAMAN\workspace\NearField\ScopeFoundryHW\ni_daq\devices\ni_counter_task.py", line 154, in read_buffer
    self.error(err)
  File "C:\Users\RAMAN\workspace\NearField\ScopeFoundryHW\ni_daq\devices\ni_task_wrap.py", line 42, in error
    logger.error('Error calling "{}": {}'.format( err.fname, err.mess ))
AttributeError: 'SamplesNoLongerAvailableError' object has no attribute 'mess'

2021-12-23T15:36:50|CRITICAL|root|Unhandled exception:Traceback (most recent call last):
  File "C:\Users\RAMAN\workspace\NearField\ScopeFoundryHW\ni_daq\devices\ni_counter_task.py", line 152, in read_buffer
    self.task.ReadCounterF64(-1, timeout, data, count, mx.byref(read_count), None)
  File "<string>", line 3, in ReadCounterF64
  File "<string>", line 2, in function
  File "C:\ProgramData\Anaconda3\lib\site-packages\PyDAQmx\DAQmxFunctions.py", line 62, in mafunction
    raise exception_class(errBuff.value.decode("utf-8"), f.__name__)
PyDAQmx.DAQmxFunctions.SamplesNoLongerAvailableError: The application is not able to keep up with the hardware acquisition.

Increasing the buffer size, reading the data more frequently, or specifying a fixed number of samples to read instead of reading all available samples might correct the problem.
Property: DAQmx_Read_RelativeTo
Corresponding Value: DAQmx_Val_CurrReadPos
Property: DAQmx_Read_Offset
Corresponding Value: 0

Task Name: _unnamedTask<0>

Status Code: -200279
 in function DAQmxReadCounterF64

During handling of the above exception, another exception occurred:

Traceback (most recent call last):
  File "_ctypes/callbacks.c", line 232, in 'calling callback function'
  File "C:\ProgramData\Anaconda3\lib\site-packages\PyDAQmx\Task.py", line 46, in EveryNCallback_py
    getattr(self,name)()
  File "C:\Users\RAMAN\workspace\NearField\ScopeFoundryHW\ni_daq\hw\ni_freq_counter_callback.py", line 87, in counter_callback
    raise err
  File "C:\Users\RAMAN\workspace\NearField\ScopeFoundryHW\ni_daq\hw\ni_freq_counter_callback.py", line 83, in counter_callback
    self.current_count = self.counter_task.read_buffer(count=self.n_samples_cb)[-1]
  File "C:\Users\RAMAN\workspace\NearField\ScopeFoundryHW\ni_daq\devices\ni_counter_task.py", line 154, in read_buffer
    self.error(err)
  File "C:\Users\RAMAN\workspace\NearField\ScopeFoundryHW\ni_daq\devices\ni_task_wrap.py", line 42, in error
    logger.error('Error calling "{}": {}'.format( err.fname, err.mess ))
AttributeError: 'SamplesNoLongerAvailableError' object has no attribute 'mess'

2021-12-23T15:36:53|CRITICAL|root|Unhandled exception:Traceback (most recent call last):
  File "C:\Users\RAMAN\workspace\NearField\ScopeFoundryHW\ni_daq\devices\ni_counter_task.py", line 152, in read_buffer
    self.task.ReadCounterF64(-1, timeout, data, count, mx.byref(read_count), None)
  File "<string>", line 3, in ReadCounterF64
  File "<string>", line 2, in function
  File "C:\ProgramData\Anaconda3\lib\site-packages\PyDAQmx\DAQmxFunctions.py", line 62, in mafunction
    raise exception_class(errBuff.value.decode("utf-8"), f.__name__)
PyDAQmx.DAQmxFunctions.SamplesNoLongerAvailableError: The application is not able to keep up with the hardware acquisition.

Increasing the buffer size, reading the data more frequently, or specifying a fixed number of samples to read instead of reading all available samples might correct the problem.
Property: DAQmx_Read_RelativeTo
Corresponding Value: DAQmx_Val_CurrReadPos
Property: DAQmx_Read_Offset
Corresponding Value: 0

Task Name: _unnamedTask<0>

Status Code: -200279
 in function DAQmxReadCounterF64

During handling of the above exception, another exception occurred:

Traceback (most recent call last):
  File "_ctypes/callbacks.c", line 232, in 'calling callback function'
  File "C:\ProgramData\Anaconda3\lib\site-packages\PyDAQmx\Task.py", line 46, in EveryNCallback_py
    getattr(self,name)()
  File "C:\Users\RAMAN\workspace\NearField\ScopeFoundryHW\ni_daq\hw\ni_freq_counter_callback.py", line 87, in counter_callback
    raise err
  File "C:\Users\RAMAN\workspace\NearField\ScopeFoundryHW\ni_daq\hw\ni_freq_counter_callback.py", line 83, in counter_callback
    self.current_count = self.counter_task.read_buffer(count=self.n_samples_cb)[-1]
  File "C:\Users\RAMAN\workspace\NearField\ScopeFoundryHW\ni_daq\devices\ni_counter_task.py", line 154, in read_buffer
    self.error(err)
  File "C:\Users\RAMAN\workspace\NearField\ScopeFoundryHW\ni_daq\devices\ni_task_wrap.py", line 42, in error
    logger.error('Error calling "{}": {}'.format( err.fname, err.mess ))
AttributeError: 'SamplesNoLongerAvailableError' object has no attribute 'mess'

2021-12-23T15:36:58|CRITICAL|root|Unhandled exception:Traceback (most recent call last):
  File "C:\Users\RAMAN\workspace\NearField\ScopeFoundryHW\ni_daq\devices\ni_counter_task.py", line 152, in read_buffer
    self.task.ReadCounterF64(-1, timeout, data, count, mx.byref(read_count), None)
  File "<string>", line 3, in ReadCounterF64
  File "<string>", line 2, in function
  File "C:\ProgramData\Anaconda3\lib\site-packages\PyDAQmx\DAQmxFunctions.py", line 62, in mafunction
    raise exception_class(errBuff.value.decode("utf-8"), f.__name__)
PyDAQmx.DAQmxFunctions.SamplesNoLongerAvailableError: The application is not able to keep up with the hardware acquisition.

Increasing the buffer size, reading the data more frequently, or specifying a fixed number of samples to read instead of reading all available samples might correct the problem.
Property: DAQmx_Read_RelativeTo
Corresponding Value: DAQmx_Val_CurrReadPos
Property: DAQmx_Read_Offset
Corresponding Value: 0

Task Name: _unnamedTask<0>

Status Code: -200279
 in function DAQmxReadCounterF64

During handling of the above exception, another exception occurred:

Traceback (most recent call last):
  File "_ctypes/callbacks.c", line 232, in 'calling callback function'
  File "C:\ProgramData\Anaconda3\lib\site-packages\PyDAQmx\Task.py", line 46, in EveryNCallback_py
    getattr(self,name)()
  File "C:\Users\RAMAN\workspace\NearField\ScopeFoundryHW\ni_daq\hw\ni_freq_counter_callback.py", line 87, in counter_callback
    raise err
  File "C:\Users\RAMAN\workspace\NearField\ScopeFoundryHW\ni_daq\hw\ni_freq_counter_callback.py", line 83, in counter_callback
    self.current_count = self.counter_task.read_buffer(count=self.n_samples_cb)[-1]
  File "C:\Users\RAMAN\workspace\NearField\ScopeFoundryHW\ni_daq\devices\ni_counter_task.py", line 154, in read_buffer
    self.error(err)
  File "C:\Users\RAMAN\workspace\NearField\ScopeFoundryHW\ni_daq\devices\ni_task_wrap.py", line 42, in error
    logger.error('Error calling "{}": {}'.format( err.fname, err.mess ))
AttributeError: 'SamplesNoLongerAvailableError' object has no attribute 'mess'

2021-12-23T15:37:05|CRITICAL|root|Unhandled exception:Traceback (most recent call last):
  File "C:\Users\RAMAN\workspace\NearField\ScopeFoundryHW\ni_daq\devices\ni_counter_task.py", line 152, in read_buffer
    self.task.ReadCounterF64(-1, timeout, data, count, mx.byref(read_count), None)
  File "<string>", line 3, in ReadCounterF64
  File "<string>", line 2, in function
  File "C:\ProgramData\Anaconda3\lib\site-packages\PyDAQmx\DAQmxFunctions.py", line 62, in mafunction
    raise exception_class(errBuff.value.decode("utf-8"), f.__name__)
PyDAQmx.DAQmxFunctions.SamplesNoLongerAvailableError: The application is not able to keep up with the hardware acquisition.

Increasing the buffer size, reading the data more frequently, or specifying a fixed number of samples to read instead of reading all available samples might correct the problem.
Property: DAQmx_Read_RelativeTo
Corresponding Value: DAQmx_Val_CurrReadPos
Property: DAQmx_Read_Offset
Corresponding Value: 0

Task Name: _unnamedTask<0>

Status Code: -200279
 in function DAQmxReadCounterF64

During handling of the above exception, another exception occurred:

Traceback (most recent call last):
  File "_ctypes/callbacks.c", line 232, in 'calling callback function'
  File "C:\ProgramData\Anaconda3\lib\site-packages\PyDAQmx\Task.py", line 46, in EveryNCallback_py
    getattr(self,name)()
  File "C:\Users\RAMAN\workspace\NearField\ScopeFoundryHW\ni_daq\hw\ni_freq_counter_callback.py", line 87, in counter_callback
    raise err
  File "C:\Users\RAMAN\workspace\NearField\ScopeFoundryHW\ni_daq\hw\ni_freq_counter_callback.py", line 83, in counter_callback
    self.current_count = self.counter_task.read_buffer(count=self.n_samples_cb)[-1]
  File "C:\Users\RAMAN\workspace\NearField\ScopeFoundryHW\ni_daq\devices\ni_counter_task.py", line 154, in read_buffer
    self.error(err)
  File "C:\Users\RAMAN\workspace\NearField\ScopeFoundryHW\ni_daq\devices\ni_task_wrap.py", line 42, in error
    logger.error('Error calling "{}": {}'.format( err.fname, err.mess ))
AttributeError: 'SamplesNoLongerAvailableError' object has no attribute 'mess'

2021-12-23T15:37:09|CRITICAL|root|Unhandled exception:Traceback (most recent call last):
  File "C:\Users\RAMAN\workspace\NearField\ScopeFoundryHW\ni_daq\devices\ni_counter_task.py", line 152, in read_buffer
    self.task.ReadCounterF64(-1, timeout, data, count, mx.byref(read_count), None)
  File "<string>", line 3, in ReadCounterF64
  File "<string>", line 2, in function
  File "C:\ProgramData\Anaconda3\lib\site-packages\PyDAQmx\DAQmxFunctions.py", line 62, in mafunction
    raise exception_class(errBuff.value.decode("utf-8"), f.__name__)
PyDAQmx.DAQmxFunctions.SamplesNoLongerAvailableError: The application is not able to keep up with the hardware acquisition.

Increasing the buffer size, reading the data more frequently, or specifying a fixed number of samples to read instead of reading all available samples might correct the problem.
Property: DAQmx_Read_RelativeTo
Corresponding Value: DAQmx_Val_CurrReadPos
Property: DAQmx_Read_Offset
Corresponding Value: 0

Task Name: _unnamedTask<0>

Status Code: -200279
 in function DAQmxReadCounterF64

During handling of the above exception, another exception occurred:

Traceback (most recent call last):
  File "_ctypes/callbacks.c", line 232, in 'calling callback function'
  File "C:\ProgramData\Anaconda3\lib\site-packages\PyDAQmx\Task.py", line 46, in EveryNCallback_py
    getattr(self,name)()
  File "C:\Users\RAMAN\workspace\NearField\ScopeFoundryHW\ni_daq\hw\ni_freq_counter_callback.py", line 87, in counter_callback
    raise err
  File "C:\Users\RAMAN\workspace\NearField\ScopeFoundryHW\ni_daq\hw\ni_freq_counter_callback.py", line 83, in counter_callback
    self.current_count = self.counter_task.read_buffer(count=self.n_samples_cb)[-1]
  File "C:\Users\RAMAN\workspace\NearField\ScopeFoundryHW\ni_daq\devices\ni_counter_task.py", line 154, in read_buffer
    self.error(err)
  File "C:\Users\RAMAN\workspace\NearField\ScopeFoundryHW\ni_daq\devices\ni_task_wrap.py", line 42, in error
    logger.error('Error calling "{}": {}'.format( err.fname, err.mess ))
AttributeError: 'SamplesNoLongerAvailableError' object has no attribute 'mess'

2021-12-23T15:37:13|CRITICAL|root|Unhandled exception:Traceback (most recent call last):
  File "C:\Users\RAMAN\workspace\NearField\ScopeFoundryHW\ni_daq\devices\ni_counter_task.py", line 152, in read_buffer
    self.task.ReadCounterF64(-1, timeout, data, count, mx.byref(read_count), None)
  File "<string>", line 3, in ReadCounterF64
  File "<string>", line 2, in function
  File "C:\ProgramData\Anaconda3\lib\site-packages\PyDAQmx\DAQmxFunctions.py", line 62, in mafunction
    raise exception_class(errBuff.value.decode("utf-8"), f.__name__)
PyDAQmx.DAQmxFunctions.SamplesNoLongerAvailableError: The application is not able to keep up with the hardware acquisition.

Increasing the buffer size, reading the data more frequently, or specifying a fixed number of samples to read instead of reading all available samples might correct the problem.
Property: DAQmx_Read_RelativeTo
Corresponding Value: DAQmx_Val_CurrReadPos
Property: DAQmx_Read_Offset
Corresponding Value: 0

Task Name: _unnamedTask<0>

Status Code: -200279
 in function DAQmxReadCounterF64

During handling of the above exception, another exception occurred:

Traceback (most recent call last):
  File "_ctypes/callbacks.c", line 232, in 'calling callback function'
  File "C:\ProgramData\Anaconda3\lib\site-packages\PyDAQmx\Task.py", line 46, in EveryNCallback_py
    getattr(self,name)()
  File "C:\Users\RAMAN\workspace\NearField\ScopeFoundryHW\ni_daq\hw\ni_freq_counter_callback.py", line 87, in counter_callback
    raise err
  File "C:\Users\RAMAN\workspace\NearField\ScopeFoundryHW\ni_daq\hw\ni_freq_counter_callback.py", line 83, in counter_callback
    self.current_count = self.counter_task.read_buffer(count=self.n_samples_cb)[-1]
  File "C:\Users\RAMAN\workspace\NearField\ScopeFoundryHW\ni_daq\devices\ni_counter_task.py", line 154, in read_buffer
    self.error(err)
  File "C:\Users\RAMAN\workspace\NearField\ScopeFoundryHW\ni_daq\devices\ni_task_wrap.py", line 42, in error
    logger.error('Error calling "{}": {}'.format( err.fname, err.mess ))
AttributeError: 'SamplesNoLongerAvailableError' object has no attribute 'mess'

2021-12-23T15:37:17|CRITICAL|root|Unhandled exception:Traceback (most recent call last):
  File "C:\Users\RAMAN\workspace\NearField\ScopeFoundryHW\ni_daq\devices\ni_counter_task.py", line 152, in read_buffer
    self.task.ReadCounterF64(-1, timeout, data, count, mx.byref(read_count), None)
  File "<string>", line 3, in ReadCounterF64
  File "<string>", line 2, in function
  File "C:\ProgramData\Anaconda3\lib\site-packages\PyDAQmx\DAQmxFunctions.py", line 62, in mafunction
    raise exception_class(errBuff.value.decode("utf-8"), f.__name__)
PyDAQmx.DAQmxFunctions.SamplesNoLongerAvailableError: The application is not able to keep up with the hardware acquisition.

Increasing the buffer size, reading the data more frequently, or specifying a fixed number of samples to read instead of reading all available samples might correct the problem.
Property: DAQmx_Read_RelativeTo
Corresponding Value: DAQmx_Val_CurrReadPos
Property: DAQmx_Read_Offset
Corresponding Value: 0

Task Name: _unnamedTask<0>

Status Code: -200279
 in function DAQmxReadCounterF64

During handling of the above exception, another exception occurred:

Traceback (most recent call last):
  File "_ctypes/callbacks.c", line 232, in 'calling callback function'
  File "C:\ProgramData\Anaconda3\lib\site-packages\PyDAQmx\Task.py", line 46, in EveryNCallback_py
    getattr(self,name)()
  File "C:\Users\RAMAN\workspace\NearField\ScopeFoundryHW\ni_daq\hw\ni_freq_counter_callback.py", line 87, in counter_callback
    raise err
  File "C:\Users\RAMAN\workspace\NearField\ScopeFoundryHW\ni_daq\hw\ni_freq_counter_callback.py", line 83, in counter_callback
    self.current_count = self.counter_task.read_buffer(count=self.n_samples_cb)[-1]
  File "C:\Users\RAMAN\workspace\NearField\ScopeFoundryHW\ni_daq\devices\ni_counter_task.py", line 154, in read_buffer
    self.error(err)
  File "C:\Users\RAMAN\workspace\NearField\ScopeFoundryHW\ni_daq\devices\ni_task_wrap.py", line 42, in error
    logger.error('Error calling "{}": {}'.format( err.fname, err.mess ))
AttributeError: 'SamplesNoLongerAvailableError' object has no attribute 'mess'

2021-12-23T15:37:21|CRITICAL|root|Unhandled exception:Traceback (most recent call last):
  File "C:\Users\RAMAN\workspace\NearField\ScopeFoundryHW\ni_daq\devices\ni_counter_task.py", line 152, in read_buffer
    self.task.ReadCounterF64(-1, timeout, data, count, mx.byref(read_count), None)
  File "<string>", line 3, in ReadCounterF64
  File "<string>", line 2, in function
  File "C:\ProgramData\Anaconda3\lib\site-packages\PyDAQmx\DAQmxFunctions.py", line 62, in mafunction
    raise exception_class(errBuff.value.decode("utf-8"), f.__name__)
PyDAQmx.DAQmxFunctions.SamplesNoLongerAvailableError: The application is not able to keep up with the hardware acquisition.

Increasing the buffer size, reading the data more frequently, or specifying a fixed number of samples to read instead of reading all available samples might correct the problem.
Property: DAQmx_Read_RelativeTo
Corresponding Value: DAQmx_Val_CurrReadPos
Property: DAQmx_Read_Offset
Corresponding Value: 0

Task Name: _unnamedTask<0>

Status Code: -200279
 in function DAQmxReadCounterF64

During handling of the above exception, another exception occurred:

Traceback (most recent call last):
  File "_ctypes/callbacks.c", line 232, in 'calling callback function'
  File "C:\ProgramData\Anaconda3\lib\site-packages\PyDAQmx\Task.py", line 46, in EveryNCallback_py
    getattr(self,name)()
  File "C:\Users\RAMAN\workspace\NearField\ScopeFoundryHW\ni_daq\hw\ni_freq_counter_callback.py", line 87, in counter_callback
    raise err
  File "C:\Users\RAMAN\workspace\NearField\ScopeFoundryHW\ni_daq\hw\ni_freq_counter_callback.py", line 83, in counter_callback
    self.current_count = self.counter_task.read_buffer(count=self.n_samples_cb)[-1]
  File "C:\Users\RAMAN\workspace\NearField\ScopeFoundryHW\ni_daq\devices\ni_counter_task.py", line 154, in read_buffer
    self.error(err)
  File "C:\Users\RAMAN\workspace\NearField\ScopeFoundryHW\ni_daq\devices\ni_task_wrap.py", line 42, in error
    logger.error('Error calling "{}": {}'.format( err.fname, err.mess ))
AttributeError: 'SamplesNoLongerAvailableError' object has no attribute 'mess'

